<?xml version="1.0" ?>
<!-- =================================================================================== -->
<!-- |    This document was autogenerated by xacro from tiago_titanium111.urdf.xacro   | -->
<!-- |    EDITING THIS FILE BY HAND IS NOT RECOMMENDED                                 | -->
<!-- =================================================================================== -->
<!--
  Copyright (c) 2011, PAL Robotics, S.L.
  All rights reserved.

  This work is licensed under the Creative Commons Attribution-NonCommercial-NoDerivs 3.0 Unported License.
  To view a copy of this license, visit http://creativecommons.org/licenses/by-nc-nd/3.0/ or send a letter to
  Creative Commons, 444 Castro Street, Suite 900, Mountain View, California, 94041, USA.
-->
<robot name="tiago" xmlns:xacro="http://www.ros.org/wiki/xacro">

  <!-- Base -->
  <link name="base_link">
    <inertial>
      <mass value="28.26649"/>
      <inertia ixx="0.46
        5" ixy="0.002" ixz="-0.001" iyy="0.483" iyz="0" izz="0.55093970"/>
    </inertial>
    <visual>
      <geometry>
        <mesh filename="tiago/meshes/base/base.stl"/>
      </geometry>
      <material name="White"/>
    </visual>
    <collision>
      <geometry>
        <mesh filename="tiago/meshes/base/base_collision.dae"/>
      </geometry>
      <material name="White"/>
    </collision>
  </link>

  <link name="wheel_right_link">
    <inertial>
      <origin  xyz="0 0 -0.00207"/>
      <mass value="1.82362"/>
      <inertia ixx="0.004" ixy="0" ixz="-0" iyy="0.004" iyz="0" izz="0"/>
    </inertial>
    <visual>
      <geometry>
        <mesh filename="tiago/meshes/wheels/wheel.stl"/>
      </geometry>
      <material name="DarkGrey"/>
    </visual>
    <collision>
      <geometry>
        <cylinder length="0.04" radius="0.0985"/>
      </geometry>
    </collision>
  </link>
  <joint name="wheel_right_joint" type="revolute">
    <parent link="base_link"/>
    <child link="wheel_right_link"/>
    <origin rpy="-1.57 0 0" xyz="0 -0.2022 0"/>
    <axis xyz="0 0 1"/>
    <limit effort="6.0" lower="-3.14" upper="3.14" velocity="10"/>
  </joint>

  <!-- Contact model for the wheel surface -->

  <link name="wheel_left_link">
    <inertial>
      <origin xyz="0 0 0.00207"/>
      <mass value="1.82362"/>
      <inertia ixx="0.004" ixy="-0.0" ixz="-0.0" iyy="0.004" iyz="0.0" izz="0.008"/>
    </inertial>
    <visual>
      <origin rpy="-3.14 0 0"/>
      <geometry>
        <mesh filename="tiago/meshes/wheels/wheel.stl"/>
      </geometry>
      <material name="DarkGrey"/>
    </visual>
    <collision>
      <geometry>
        <cylinder length="0.04" radius="0.0985"/>
      </geometry>
    </collision>
  </link>
  <joint name="wheel_left_joint" type="revolute">
    <parent link="base_link"/>
    <child link="wheel_left_link"/>
    <origin rpy="-1.57 0 0" xyz="0 0.2022 0"/>
    <axis xyz="0 0 1"/>
    <limit effort="6.0" lower="-3.14" upper="3.14" velocity="10"/>
  </joint>
  <!-- Bottom fixed part of column -->
  <link name="torso_fixed_link">
    <inertial>
      <origin  xyz="0.02435 -0.00464 0.15900"/>
      <mass value="14.01360"/>
      <inertia ixx="0.38341100000" ixy="0.00036400000" ixz="-0.02438900000" iyy="0.40577300000" iyz="-0.00078200000" izz="0.07699800000"/>
    </inertial>
    <visual>
      <geometry>
        <mesh filename="tiago/meshes/torso/torso_fix.stl" scale="1 1 1"/>
      </geometry>
      <material name="LightGrey"/>
    </visual>
    <collision>
      <origin xyz="0.085 0.0 0.02"/>
      <geometry>
        <box size="0.4 0.25 0.04"/>
      </geometry>
    </collision>
    <collision>
      <origin  xyz="0 0 0.05"/>
      <geometry>
        <box size="0.25 0.25 0.1"/>
      </geometry>
    </collision>
  </link>
  <joint name="torso_fixed_joint" type="fixed">
    <origin  xyz="-0.062 0.0 0.193"/>
    <parent link="base_link"/>
    <child link="torso_fixed_link"/>
  </joint>
  <!-- Middle extending  -->
  <link name="torso_fixed_column_link">
    <inertial>
      <mass value="0.01"/>
      <inertia ixx="0.000001" ixy="0" ixz="0" iyy="0.000001" iyz="0" izz="0.000001"/>
    </inertial>
    <visual>
      <origin  xyz="0 0 0.275"/>
      <geometry>
        <box size="0.18 0.2 0.55"/>
      </geometry>
      <material name="DarkGrey"/>
    </visual>
    <collision>
      <origin  xyz="0 0 0.275"/>
      <geometry>
        <box size="0.20 0.20 0.55"/>
      </geometry>
      <material name="DarkGrey"/>
    </collision>
  </link>

  <joint name="torso_fixed_column_joint" type="fixed">
    <origin  xyz="-0.062 0 0.195"/>
    <parent link="base_link"/>
    <child link="torso_fixed_column_link"/>
  </joint>

  <link name="torso_lift_link">
    <inertial>
      <origin  xyz="0.04361 -0.00116 -0.17334"/>
      <mass value="6.93198"/>
      <inertia ixx="0.24487000000" ixy="-0.00145600000" ixz="-0.00974200000" iyy="0.24926900000" iyz="0.00828100000" izz="0.09039500000"/>
    </inertial>
    <!-- Lifting body -->
    <visual>
      <geometry>
        <mesh filename="tiago/meshes/torso/torso_lift_with_arm.stl" scale="1 1 1"/>
      </geometry>
      <material name="White"/>
    </visual>
    <collision>
      <geometry>
        <mesh filename="tiago/meshes/torso/torso_lift_collision.dae" scale="1 1 1"/>
      </geometry>
      <material name="LightGrey"/>
    </collision>
  </link>
  <joint name="torso_lift_joint" type="prismatic">
    <origin xyz="0.0 0.0 0.597"/>
    <parent link="torso_fixed_link"/>
    <child link="torso_lift_link"/>
    <axis xyz="0 0 1"/>
    <limit effort="2000" lower="0" upper="0.35" velocity="0.07"/>
    <calibration rising="0.0"/>
    <dynamics damping="1000"/>
    <safety_controller k_position="20" k_velocity="20" soft_lower_limit="0.0" soft_upper_limit="0.35"/>
  </joint>

  <link name="head_1_link">
    <inertial>
      <origin rpy="0.00000 0.00000 0.00000" xyz="-0.00508 0.00237 0.07229"/>
      <mass value="0.62220"/>
      <inertia ixx="0.00119200000" ixy="-0.00000700000" ixz="0.00009600000" iyy="0.00140200000" iyz="0.00000400000" izz="0.00088900000"/>
    </inertial>
    <visual>
      <origin rpy="0 0 0" xyz="0 0 0"/>
      <geometry>
        <mesh filename="tiago/meshes/head/head_1.stl" scale="1 1 1"/>
      </geometry>
      <material name="White"/>
    </visual>
    <collision>
      <origin rpy="0 0 0.0" xyz="0.0 0 0"/>
      <geometry>
        <mesh filename="tiago/meshes/head/head_1_collision.dae" scale="1 1 1"/>
      </geometry>
      <material name="White"/>
    </collision>
  </link>
  <joint name="head_1_joint" type="revolute">
    <parent link="torso_lift_link"/>
    <child link="head_1_link"/>
    <origin rpy="0 0 0" xyz="0.182 0.0 0.0"/>
    <axis xyz="0 0 1"/>
    <limit effort="5.197" lower="-1.308996939" upper="1.308996939" velocity="3.0"/>
    <dynamics damping="0.5" friction="1.0"/>
    <safety_controller k_position="20" k_velocity="20" soft_lower_limit="-1.288996939" soft_upper_limit="1.288996939"/>
  </joint>



  <link name="head_2_link">
    <inertial>
      <origin rpy="0.00000 0.00000 0.00000" xyz="0.04700 0.05542 0.00022"/>
      <mass value="0.66123"/>
      <inertia ixx="0.00462000000" ixy="0.00068900000" ixz="0.00000600000" iyy="0.00486100000" iyz="0.00000600000" izz="0.00313200000"/>
    </inertial>
    <visual>
      <origin rpy="0 0 0" xyz="0 0 0"/>
      <geometry>
        <mesh filename="tiago/meshes/head/head_2.stl" scale="1 1 1"/>
      </geometry>
      <material name="White"/>
    </visual>
    <collision>
      <origin rpy="0 0 0" xyz="0 0 0"/>
      <geometry>
        <mesh filename="tiago/meshes/head/head_2_collision.dae" scale="1 1 1"/>
      </geometry>
    </collision>
  </link>
  <joint name="head_2_joint" type="revolute">
    <parent link="head_1_link"/>
    <child link="head_2_link"/>
    <origin rpy="1.57079632679 0 0" xyz="0.005 0.0 0.098"/>
    <axis xyz="0 0 1"/>
    <limit effort="2.77" lower="-1.0471975512" upper="0.785398163397" velocity="3.0"/>
    <dynamics damping="0.5" friction="1.0"/>
    <safety_controller k_position="20" k_velocity="20" soft_lower_limit="-1.0271975512" soft_upper_limit="0.785398163397"/>
  </joint>



  <!--************************-->
  <!--        SHOULDER        -->
  <!--************************-->
  <link name="arm_1_link">
    <inertial>
      <origin rpy="0.00000 0.00000 0.00000" xyz="0.08169 0.01822 -0.01884"/>
      <mass value="2.31325"/>
      <inertia ixx="0.00269400000" ixy="0.00115700000" ixz="-0.00142300000" iyy="0.00704100000" iyz="-0.00031200000" izz="0.00731200000"/>
    </inertial>
    <!-- M90 module -->
    <visual>
      <origin rpy="0 0 0" xyz="0 0 0"/>
      <geometry>
        <mesh filename="tiago/meshes/arm/arm_1.stl" scale="1 1 1"/>
      </geometry>
      <material name="White"/>
    </visual>
    <collision>
      <origin rpy="0 0 0" xyz="0 0 0"/>
      <geometry>
        <mesh filename="tiago/meshes/arm/arm_1_collision.dae" scale="1 1 1"/>
      </geometry>
    </collision>
  </link>

  <joint name="arm_1_joint" type="revolute">
    <parent link="torso_lift_link"/>
    <child link="arm_1_link"/>
    <origin rpy="0 0 -1.57079632679" xyz="0.15505 0.014 -0.151"/>
    <axis xyz="0 0 1"/>
    <limit effort="39.0" lower="0.0" upper="2.74889357189" velocity="2.7"/>
    <dynamics damping="1.0" friction="1.0"/>
    <safety_controller k_position="20" k_velocity="20" soft_lower_limit="0.02" soft_upper_limit="2.72889357189"/>
  </joint>
  <link name="arm_2_link">
    <inertial>
      <origin rpy="0.00000 0.00000 0.00000" xyz="-0.03609 -0.00006 0.01649"/>
      <mass value="1.10224"/>
      <inertia ixx="0.00114600000" ixy="0.00000100000" ixz="0.00043500000" iyy="0.00218200000" iyz="-0.00000100000" izz="0.00237300000"/>
    </inertial>
    <visual>
      <!-- <origin xyz="0 0 0" rpy="${180 * deg_to_rad} ${0 * deg_to_rad} ${-90 * deg_to_rad}" /> -->
      <origin rpy="0.0 0.0 0.0" xyz="0 0 0"/>
      <geometry>
        <mesh filename="tiago/meshes/arm/arm_2.stl" scale="1 1 1"/>
      </geometry>
      <material name="DarkGrey"/>
    </visual>
    <collision>
      <!-- <origin xyz="0 0 0" rpy="${180 * deg_to_rad} ${0 * deg_to_rad} ${-90 * deg_to_rad}" /> -->
      <origin rpy="0.0 0.0 0.0" xyz="0 0 0"/>
      <geometry>
        <mesh filename="tiago/meshes/arm/arm_2_collision.dae" scale="1 1 1"/>
      </geometry>
    </collision>
  </link>
  <joint name="arm_2_joint" type="revolute">
    <parent link="arm_1_link"/>
    <child link="arm_2_link"/>
    <origin rpy="1.57079632679 0.0 0.0" xyz="0.125 0.0165 -0.031"/>
    <axis xyz="0 0 1"/>
    <limit effort="39.0" lower="-1.57079632679" upper="1.0908307825" velocity="3.66"/>
    <dynamics damping="1.0" friction="1.0"/>
    <safety_controller k_position="20" k_velocity="20" soft_lower_limit="-1.55079632679" soft_upper_limit="1.0708307825"/>
  </joint>
  <link name="arm_3_link">
    <inertial>
      <origin rpy="0.00000 0.00000 0.00000" xyz="0.00752 0.00244 0.12957"/>
      <mass value="2.42460"/>
      <inertia ixx="0.01441800000" ixy="0.00008400000" ixz="0.00114300000" iyy="0.01478800000" iyz="0.00064200000" izz="0.00256000000"/>
    </inertial>
    <visual>
      <origin rpy="0 0 0" xyz="0 0 0"/>
      <geometry>
        <mesh filename="tiago/meshes/arm/arm_3.stl" scale="1 1 1"/>
      </geometry>
      <material name="DarkGrey"/>
    </visual>
    <collision>
      <origin rpy="0 0 0" xyz="0 0 0"/>
      <geometry>
        <mesh filename="tiago/meshes/arm/arm_3_collision.dae" scale="1 1 1"/>
      </geometry>
    </collision>
  </link>
  <joint name="arm_3_joint" type="revolute">
    <parent link="arm_2_link"/>
    <child link="arm_3_link"/>
    <origin rpy="-1.57079632679 0.0 1.57079632679" xyz="0.0895 0.0 0.0015"/>
    <axis xyz="0 0 1"/>
    <limit effort="17.86" lower="-3.53429173529" upper="1.57079632679" velocity="4.58"/>
    <dynamics damping="1.0" friction="1.0"/>
    <safety_controller k_position="20" k_velocity="20" soft_lower_limit="-3.51429173529" soft_upper_limit="1.55079632679"/>
  </joint>
  <!--************************-->
  <!--        ELBOW           -->
  <!--************************-->
  <link name="arm_4_link">
    <inertial>
      <origin rpy="0.00000 0.00000 0.00000" xyz="0.07426 -0.01306 0.01549"/>
      <mass value="1.45429"/>
      <inertia ixx="0.00195300000" ixy="-0.00059600000" ixz="0.00088000000" iyy="0.00709700000" iyz="-0.00017100000" izz="0.00740500000"/>
    </inertial>
    <visual>
      <origin rpy="0 0 0" xyz="0 0 0"/>
      <geometry>
        <mesh filename="tiago/meshes/arm/arm_4.stl" scale="1 1 1"/>
      </geometry>
      <material name="DarkGrey"/>
    </visual>
    <collision>
      <origin rpy="0 0 0" xyz="0 0 0"/>
      <geometry>
        <mesh filename="tiago/meshes/arm/arm_4_collision.dae" scale="1 1 1"/>
      </geometry>
    </collision>
  </link>
  <joint name="arm_4_joint" type="revolute">
    <parent link="arm_3_link"/>
    <child link="arm_4_link"/>
    <origin rpy="-1.57079632679 -1.57079632679 0.0" xyz="-0.02 -0.027 -0.222"/>
    <axis xyz="0 0 1"/>
    <limit effort="17.86" lower="-0.392699081699" upper="2.35619449019" velocity="4.58"/>
    <dynamics damping="1.0" friction="1.0"/>
    <safety_controller k_position="20" k_velocity="20" soft_lower_limit="-0.372699081699" soft_upper_limit="2.33619449019"/>
  </joint>



  <!--************************-->
  <!--        WRIST           -->
  <!--************************-->
  <link name="arm_5_link">
    <inertial>
      <origin rpy="0.00000 0.00000 0.00000" xyz="0.00003 -0.00028 0.07831"/>
      <mass value="1.07424"/>
      <inertia ixx="0.00168000000" ixy="0.00000100000" ixz="-0.00001500000" iyy="0.00160300000" iyz="-0.00001900000" izz="0.00040400000"/>
    </inertial>
    <visual>
      <origin rpy="0 0 0" xyz="0 0 0"/>
      <geometry>
        <mesh filename="tiago/meshes/arm/arm_5.stl" scale="1 1 1"/>
      </geometry>
      <material name="LightGrey"/>
    </visual>
    <collision>
      <origin rpy="0 0 0" xyz="0 0 0"/>
      <geometry>
        <mesh filename="tiago/meshes/arm/arm_5_collision.dae" scale="1 1 1"/>
      </geometry>
    </collision>
  </link>
  <joint name="arm_5_joint" type="revolute">
    <parent link="arm_4_link"/>
    <child link="arm_5_link"/>
    <origin rpy="0.0 -1.57079632679 0.0" xyz="-0.162 0.02 0.027"/>
    <axis xyz="0 0 1"/>
    <limit effort="3" lower="-2.09439510239" upper="2.09439510239" velocity="1.95"/>
    <dynamics damping="1.0" friction="1.0"/>
    <safety_controller k_position="20" k_velocity="20" soft_lower_limit="-2.07439510239" soft_upper_limit="2.07439510239"/>
  </joint>
  <link name="arm_6_link">
    <inertial>
      <origin rpy="0.00000 0.00000 0.00000" xyz="0.00531 0.00021 0.00002"/>
      <mass value="0.28722"/>
      <inertia ixx="0.00005900000" ixy="-0.00000000000" ixz="-0.00000000000" iyy="0.00010600000" iyz="0.00000000000" izz="0.00012600000"/>
    </inertial>
    <visual>
      <origin rpy="0 0 0" xyz="0 0 0"/>
      <geometry>
        <mesh filename="tiago/meshes/arm/arm_6.stl" scale="1 1 1"/>
      </geometry>
      <material name="LightGrey"/>
    </visual>
    <collision>
      <origin rpy="0 0 0" xyz="0 0 0"/>
      <geometry>
        <mesh filename="tiago/meshes/arm/arm_6_collision.dae" scale="1 1 1"/>
      </geometry>
    </collision>
  </link>
  <joint name="arm_6_joint" type="revolute">
    <parent link="arm_5_link"/>
    <child link="arm_6_link"/>
    <origin rpy="0.0 -1.57079632679 -1.57079632679" xyz="0 0 0.15"/>
    <axis xyz="0 0 1"/>
    <limit effort="6.6" lower="-1.41371669412" upper="1.41371669412" velocity="1.76"/>
    <dynamics damping="1.0" friction="1.0"/>
    <safety_controller k_position="20" k_velocity="20" soft_lower_limit="-1.39371669412" soft_upper_limit="1.39371669412"/>
  </joint>


  <link name="arm_7_link">
    <inertial>
      <origin rpy="0.00000 0.00000 0.00000" xyz="0.00011 -0.00034 0.02405"/>
      <mass value="0.05935"/>
      <inertia ixx="0.00001400000" ixy="-0.00000000000" ixz="-0.00000000000" iyy="0.00001400000" iyz="0.00000000000" izz="0.00000400000"/>
    </inertial>
    <visual>
      <origin rpy="0 0 0" xyz="0 0 0"/>
      <geometry>
        <cylinder length="0.0001" radius="0.0001"/>
      </geometry>
      <material name="LightGrey"/>
    </visual>
    <collision>
      <origin rpy="0 0 0" xyz="0 0 0"/>
      <geometry>
        <cylinder length="0.0001" radius="0.0001"/>
      </geometry>
    </collision>
  </link>
  <joint name="arm_7_joint" type="revolute">
    <parent link="arm_6_link"/>
    <child link="arm_7_link"/>
    <origin rpy="1.57079632679 0.0 1.57079632679" xyz="0 0 0"/>
    <axis xyz="0 0 1"/>
    <limit effort="6.6" lower="-2.09439510239" upper="2.09439510239" velocity="1.76"/>
    <dynamics damping="1.0" friction="1.0"/>
    <safety_controller k_position="20" k_velocity="20" soft_lower_limit="-2.07439510239" soft_upper_limit="2.07439510239"/>
  </joint>








  <!--***********************-->
  <!--        TOOL           -->
  <!--***********************-->
  <link name="arm_tool_link">
    <inertial>
      <mass value="0.1"/>
      <inertia ixx="0.0" ixy="0.0" ixz="0.0" iyy="0.0" iyz="0.0" izz="0.0"/>
    </inertial>
    <visual>
      <origin rpy="0 1.57079632679 0" xyz="0.001 0 0"/>
      <geometry>
        <cylinder length="0.0005" radius="0.005"/>
      </geometry>
      <material name="LightGrey"/>
    </visual>
    <collision>
      <origin rpy="0 1.57079632679 0" xyz="0.001 0 0"/>
      <geometry>
        <cylinder length="0.0005" radius="0.005"/>
      </geometry>
    </collision>
  </link>
  <joint name="arm_tool_joint" type="fixed">
    <parent link="arm_7_link"/>
    <child link="arm_tool_link"/>
    <origin rpy="1.57079632679 -1.57079632679 3.14159265359" xyz="0 0 0.046"/>
  </joint>




  <!--************************-->
  <!--        ft sensor       -->
  <!--************************-->
  <link name="wrist_ft_link">
    <inertial>
      <mass value="0.1"/>
      <inertia ixx="0.0" ixy="0.0" ixz="0.0" iyy="0.0" iyz="0.0" izz="0.0"/>
    </inertial>
    <visual>
      <origin rpy="0 0 0" xyz="0 0 0"/>
      <geometry>
        <cylinder length="0.01" radius="0.0225"/>
      </geometry>
      <material name="LightGrey"/>
    </visual>
    <collision>
      <origin rpy="0 0 0" xyz="0 0 0"/>
      <geometry>
        <cylinder length="0.01" radius="0.0225"/>
      </geometry>
    </collision>
  </link>
  <joint name="wrist_ft_joint" type="fixed">
    <parent link="arm_tool_link"/>
    <child link="wrist_ft_link"/>
    <origin rpy="1.57079632679 0 1.57079632679" xyz="0.00785 0 0"/>
  </joint>
  <!--***********************-->
  <!--       FT TOOL         -->
  <!--***********************-->
  <link name="wrist_ft_tool_link">
    <inertial>
      <mass value="0.1"/>
      <inertia ixx="0.0" ixy="0.0" ixz="0.0" iyy="0.0" iyz="0.0" izz="0.0"/>
    </inertial>
    <visual>
      <origin rpy="0 1.57079632679 0" xyz="0.0 0 0"/>
      <geometry>
        <cylinder length="0.00975" radius="0.025"/>
      </geometry>
      <material name="FlatBlack"/>
    </visual>
    <collision>
      <origin rpy="0 1.57079632679 0" xyz="0.0 0 0"/>
      <geometry>
        <cylinder length="0.00975" radius="0.025"/>
      </geometry>
    </collision>
  </link>
  <joint name="wrist_tool_joint" type="fixed">
    <parent link="wrist_ft_link"/>
    <child link="wrist_ft_tool_link"/>
    <origin rpy="-1.57079632679 -1.57079632679 0" xyz="0 0 0.012725"/>
  </joint>
  <joint name="hand_palm_joint" type="fixed">
    <parent link="wrist_ft_tool_link"/>
    <child link="hand_palm_link"/>
    <origin rpy="0 0 0" xyz="0 0 0"/>
  </joint>
  <!--***********************-->
  <!--       FT TOOL         -->
  <!--***********************-->
  <joint name="hand_palm_joint" type="fixed">
    <parent link="wrist_ft_link"/>
    <child link="hand_palm_link"/>
    <origin rpy="1.57 -1.57 0" xyz="0 0 0.0105"/>
  </joint>
  <link name="hand_palm_link">
    <inertial>
      <origin rpy="0 0 0" xyz="0.0641 -0.0022 0.0021"/>
      <!-- NOTE: Less than total palm mass of 0.598kg because actuator masses are specified separately -->
      <mass value="0.4"/>
      <inertia ixx="0.000305100" ixy="0.000005037" ixz="0.000015302" iyy="0.000811920" iyz="0.000007622" izz="0.000655851"/>
    </inertial>
    <visual>
      <origin rpy="0 0 0" xyz="0 0 0"/>
      <geometry>
        <mesh filename="tiago/meshes/palm.stl" scale="1 1 1"/>
      </geometry>
      <material name="Hey5DarkGrey"/>
    </visual>
    <collision>
      <origin rpy="0 0 0" xyz="0 0 0"/>
      <geometry>
        <mesh filename="tiago/meshes/palm.stl" scale="1 1 1"/>
      </geometry>
    </collision>
  </link>

  <joint name="hand_thumb_joint" type="revolute">
    <parent link="hand_palm_link"/>
    <child link="hand_thumb_link"/>
    <origin rpy="0 0 0" xyz="0 0 0"/>
    <axis xyz="0 0 1"/>
    <limit effort="2.0" lower="-2.61799387799" upper="6.28318530718" velocity="3.35"/>
    <dynamics damping="0.5" friction="0.0"/>
    <!-- TODO: Tune -->
    <safety_controller k_position="20" k_velocity="20" soft_lower_limit="-2.61799387799" soft_upper_limit="6.28318530718"/>
  </joint>
  <link name="hand_thumb_link">
    <inertial>
      <origin rpy="0 0 0" xyz="0 0 0"/>
      <mass value="0.05"/>
      <inertia ixx="0.001" ixy="0" ixz="0" iyy="0.001" iyz="0" izz="0.001"/>
      <!--To stabilize simulation-->
    </inertial>
    <visual>
      <origin rpy="0 0 0" xyz="0 0 0"/>
      <geometry>
        <sphere radius="0.001"/>
      </geometry>
      <material name="Hey5DarkGrey"/>
    </visual>
    <collision>
      <origin rpy="0 0 0" xyz="0 0 0"/>
      <geometry>
        <sphere radius="0.001"/>
      </geometry>
    </collision>
  </link>

  <joint name="hand_index_joint" type="revolute">
    <parent link="hand_palm_link"/>
    <child link="hand_index_link"/>
    <origin rpy="0 0 0" xyz="0 0 0"/>
    <axis xyz="0 0 1"/>
    <limit effort="2.0" lower="-3.05432619099" upper="6.80678408278" velocity="3.35"/>
    <dynamics damping="0.5" friction="0.0"/>
    <!-- TODO: Tune -->
    <safety_controller k_position="20" k_velocity="20" soft_lower_limit="-3.05432619099" soft_upper_limit="6.80678408278"/>
  </joint>
  <link name="hand_index_link">
    <inertial>
      <origin rpy="0 0 0" xyz="0 0 0"/>
      <mass value="0.05"/>
      <inertia ixx="0.001" ixy="0" ixz="0" iyy="0.001" iyz="0" izz="0.001"/>
      <!--To stabilize simulation-->
    </inertial>
    <visual>
      <origin rpy="0 0 0" xyz="0 0 0"/>
      <geometry>
        <sphere radius="0.001"/>
      </geometry>
      <material name="Hey5DarkGrey"/>
    </visual>
    <collision>
      <origin rpy="0 0 0" xyz="0 0 0"/>
      <geometry>
        <sphere radius="0.001"/>
      </geometry>
    </collision>
  </link>


  <joint name="hand_thumb_abd_joint" type="fixed">
    <parent link="hand_palm_link"/>
    <child link="hand_thumb_abd_link"/>
    <origin rpy="0 -1.1344640138 0" xyz="0.0901 0.0134 0.038"/>
    <axis xyz="0 0 1"/>
    <limit effort="2.0" lower="0.0" upper="1.57079632679" velocity="2.0"/>
    <dynamics damping="0.5" friction="0.0"/>
  </joint>
  <link name="hand_thumb_abd_link">
    <inertial>
      <origin rpy="0 0 0" xyz="-0.0132 0.0037 -0.0017"/>
      <mass value="0.014"/>
      <inertia ixx="0.001" ixy="0" ixz="0" iyy="0.001" iyz="0" izz="0.001"/>
      <!-- To stabilize simulation -->
    </inertial>
    <visual>
      <origin rpy="0 0 0" xyz="0 0 0"/>
      <geometry>
        <mesh filename="tiago/meshes/thumb_abd_collision.stl" scale="1 1 1"/>
      </geometry>
      <material name="Hey5DarkGrey"/>
    </visual>
    <collision>
      <origin rpy="0 0 0" xyz="0 0 0"/>
      <geometry>
        <mesh filename="tiago/meshes/thumb_abd_collision.stl" scale="1 1 1"/>
      </geometry>
    </collision>
  </link>


  <joint name="hand_thumb_flex_1_joint" type="revolute">
    <parent link="hand_thumb_abd_link"/>
    <child link="hand_thumb_flex_1_link"/>
    <origin rpy="-1.14423785761 0 0" xyz="0.0355 0.003 0.005"/>
    <axis xyz="0 0 1"/>
    <limit effort="2.0" lower="0.0" upper="0.785398163397" velocity="2.0"/>
    <dynamics damping="0.5" friction="0.0"/>
  </joint>
  <link name="hand_thumb_flex_1_link">
    <inertial>
      <origin rpy="0 0 0" xyz="0.0047 0.0031 0.0"/>
      <mass value="0.009"/>
      <inertia ixx="0.001" ixy="0" ixz="0" iyy="0.001" iyz="0" izz="0.001"/>
      <!-- To stabilize simulation -->
    </inertial>
    <visual>
      <origin rpy="0 0 0" xyz="0 0 0"/>
      <geometry>
        <mesh filename="tiago/meshes/finger_flex_collision.stl"/>
      </geometry>
      <material name="Hey5DarkGrey"/>
    </visual>
    <collision>
      <origin rpy="0 0 0" xyz="0 0 0"/>
      <geometry>
        <mesh filename="tiago/meshes/finger_flex_collision.stl"/>
      </geometry>
    </collision>
  </link>

  <joint name="hand_thumb_virtual_2_joint" type="revolute">
    <parent link="hand_thumb_flex_1_link"/>
    <child link="hand_thumb_virtual_2_link"/>
    <origin rpy="0 0 0" xyz="0.009 0 0"/>
    <axis xyz="0 0 1"/>
    <limit effort="2.0" lower="0.0" upper="0.785398163397" velocity="2.0"/>
    <dynamics damping="0.5" friction="0.0"/>
  </joint>
  <link name="hand_thumb_virtual_2_link">
    <inertial>
      <origin rpy="0 0 0" xyz="0.0065 0 0"/>
      <mass value="0.01"/>
      <!--TODO: can we make it zero and still have a stable dynamic simulation?-->
      <inertia ixx="0.001" ixy="0" ixz="0" iyy="0.001" iyz="0" izz="0.001"/>
      <!-- To stabilize simulation -->
    </inertial>
    <visual>
      <origin rpy="0 0 0" xyz="0.0065 0 0"/>
      <geometry>
        <box size="0.013 0.002 0.012"/>
      </geometry>
      <material name="Hey5DarkGrey"/>
    </visual>
    <collision>
      <origin rpy="0 0 0" xyz="0 0 0"/>
      <geometry>
        <box size="0.013 0.002 0.012"/>
      </geometry>
    </collision>
  </link>

  <joint name="hand_thumb_flex_2_joint" type="revolute">
    <parent link="hand_thumb_virtual_2_link"/>
    <child link="hand_thumb_flex_2_link"/>
    <origin rpy="0 0 0" xyz="0.013 0 0"/>
    <axis xyz="0 0 1"/>
    <limit effort="2.0" lower="0.0" upper="0.785398163397" velocity="2.0"/>
    <dynamics damping="0.5" friction="0.0"/>
  </joint>
  <link name="hand_thumb_flex_2_link">
    <inertial>
      <origin rpy="0 0 0" xyz="0.0096 0.003 0.0"/>
      <mass value="0.015"/>
      <inertia ixx="0.001" ixy="0" ixz="0" iyy="0.001" iyz="0" izz="0.001"/>
      <!-- To stabilize simulation -->
    </inertial>
    <visual>
      <origin rpy="0 0 0" xyz="0 0 0"/>
      <geometry>
        <mesh filename="tiago/meshes/finger_flex_tip_collision.stl"/>
      </geometry>
      <material name="Hey5DarkGrey"/>
    </visual>
    <collision>
      <origin rpy="0 0 0" xyz="0 0 0"/>
      <geometry>
        <mesh filename="tiago/meshes/finger_flex_tip_collision.stl"/>
      </geometry>
    </collision>
  </link>

  <joint name="hand_index_abd_joint" type="fixed">
    <parent link="hand_palm_link"/>
    <child link="hand_index_abd_link"/>
    <origin rpy="-1.57079632679 -0.523598775598 0" xyz="0.1265 0.0042 0.0265"/>
    <axis xyz="0 0 1"/>
    <limit effort="2.0" lower="-0.523598775598" upper="0.523598775598" velocity="2.0"/>
    <dynamics damping="0.5" friction="0.0"/>
  </joint>
  <link name="hand_index_abd_link">
    <inertial>
      <origin rpy="0 0 0" xyz="-0.0018 0.0 0.0028"/>
      <mass value="0.018"/>
      <inertia ixx="0.001" ixy="0" ixz="0" iyy="0.001" iyz="0" izz="0.001"/>
      <!-- To stabilize simulation -->
    </inertial>
    <visual>
      <origin rpy="0 0 0" xyz="0 0 0"/>
      <geometry>
        <mesh filename="tiago/meshes/finger_abd_collision.stl" scale="1 1 1"/>
      </geometry>
      <material name="Hey5DarkGrey"/>
    </visual>
    <collision>
      <origin rpy="0 0 0" xyz="0 0 0"/>
      <geometry>
        <mesh filename="tiago/meshes/finger_abd_collision.stl" scale="1 1 1"/>
      </geometry>
    </collision>
  </link>

  <joint name="hand_index_virtual_1_joint" type="revolute">
    <parent link="hand_index_abd_link"/>
    <child link="hand_index_virtual_1_link"/>
    <origin rpy="1.57079632679 0 0" xyz="0.009 0 0"/>
    <axis xyz="0 0 1"/>
    <limit effort="2.0" lower="0.0" upper="0.785398163397" velocity="2.0"/>
    <dynamics damping="0.5" friction="0.0"/>
  </joint>
  <link name="hand_index_virtual_1_link">
    <inertial>
      <origin rpy="0 0 0" xyz="0.0065 0 0"/>
      <mass value="0.01"/>
      <!--TODO: can we make it zero and still have a stable dynamic simulation?-->
      <inertia ixx="0.001" ixy="0" ixz="0" iyy="0.001" iyz="0" izz="0.001"/>
      <!-- To stabilize simulation -->
    </inertial>
    <visual>
      <origin rpy="0 0 0" xyz="0.0065 0 0"/>
      <geometry>
        <box size="0.013 0.002 0.012"/>
      </geometry>
      <material name="Hey5DarkGrey"/>
    </visual>
    <collision>
      <origin rpy="0 0 0" xyz="0 0 0"/>
      <geometry>
        <box size="0.013 0.002 0.012"/>
      </geometry>
    </collision>
  </link>

  <joint name="hand_index_flex_1_joint" type="revolute">
    <parent link="hand_index_virtual_1_link"/>
    <child link="hand_index_flex_1_link"/>
    <origin rpy="0 0 0" xyz="0.013 0 0"/>
    <axis xyz="0 0 1"/>
    <limit effort="2.0" lower="0.0" upper="0.785398163397" velocity="2.0"/>
    <dynamics damping="0.5" friction="0.0"/>
  </joint>
  <link name="hand_index_flex_1_link">
    <inertial>
      <origin rpy="0 0 0" xyz="0.0047 0.0031 0.0"/>
      <mass value="0.009"/>
      <inertia ixx="0.001" ixy="0" ixz="0" iyy="0.001" iyz="0" izz="0.001"/>
      <!-- To stabilize simulation -->
    </inertial>
    <visual>
      <origin rpy="0 0 0" xyz="0 0 0"/>
      <geometry>
        <mesh filename="tiago/meshes/finger_flex_collision.stl"/>
      </geometry>
      <material name="Hey5DarkGrey"/>
    </visual>
    <collision>
      <origin rpy="0 0 0" xyz="0 0 0"/>
      <geometry>
        <mesh filename="tiago/meshes/finger_flex_collision.stl"/>
      </geometry>
    </collision>
  </link>

  <joint name="hand_index_virtual_2_joint" type="revolute">
    <parent link="hand_index_flex_1_link"/>
    <child link="hand_index_virtual_2_link"/>
    <origin rpy="0 0 0" xyz="0.009 0 0"/>
    <axis xyz="0 0 1"/>
    <limit effort="2.0" lower="0.0" upper="0.785398163397" velocity="2.0"/>
    <dynamics damping="0.5" friction="0.0"/>
  </joint>
  <link name="hand_index_virtual_2_link">
    <inertial>
      <origin rpy="0 0 0" xyz="0.0065 0 0"/>
      <mass value="0.01"/>
      <!--TODO: can we make it zero and still have a stable dynamic simulation?-->
      <inertia ixx="0.001" ixy="0" ixz="0" iyy="0.001" iyz="0" izz="0.001"/>
      <!-- To stabilize simulation -->
    </inertial>
    <visual>
      <origin rpy="0 0 0" xyz="0.0065 0 0"/>
      <geometry>
        <box size="0.013 0.002 0.012"/>
      </geometry>
      <material name="Hey5DarkGrey"/>
    </visual>
    <collision>
      <origin rpy="0 0 0" xyz="0 0 0"/>
      <geometry>
        <box size="0.013 0.002 0.012"/>
      </geometry>
    </collision>
  </link>

  <joint name="hand_index_flex_2_joint" type="revolute">
    <parent link="hand_index_virtual_2_link"/>
    <child link="hand_index_flex_2_link"/>
    <origin rpy="0 0 0" xyz="0.013 0 0"/>
    <axis xyz="0 0 1"/>
    <limit effort="2.0" lower="0.0" upper="0.785398163397" velocity="2.0"/>
    <dynamics damping="0.5" friction="0.0"/>
  </joint>
  <link name="hand_index_flex_2_link">
    <inertial>
      <origin rpy="0 0 0" xyz="0.0047 0.0031 0.0"/>
      <mass value="0.009"/>
      <inertia ixx="0.001" ixy="0" ixz="0" iyy="0.001" iyz="0" izz="0.001"/>
      <!-- To stabilize simulation -->
    </inertial>
    <visual>
      <origin rpy="0 0 0" xyz="0 0 0"/>
      <geometry>
        <mesh filename="tiago/meshes/finger_flex_collision.stl"/>
      </geometry>
      <material name="Hey5DarkGrey"/>
    </visual>
    <collision>
      <origin rpy="0 0 0" xyz="0 0 0"/>
      <geometry>
        <mesh filename="tiago/meshes/finger_flex_collision.stl"/>
      </geometry>
    </collision>
  </link>

  <joint name="hand_index_virtual_3_joint" type="revolute">
    <parent link="hand_index_flex_2_link"/>
    <child link="hand_index_virtual_3_link"/>
    <origin rpy="0 0 0" xyz="0.009 0 0"/>
    <axis xyz="0 0 1"/>
    <limit effort="2.0" lower="0.0" upper="0.785398163397" velocity="2.0"/>
    <dynamics damping="0.5" friction="0.0"/>
  </joint>
  <link name="hand_index_virtual_3_link">
    <inertial>
      <origin rpy="0 0 0" xyz="0.0065 0 0"/>
      <mass value="0.01"/>
      <!--TODO: can we make it zero and still have a stable dynamic simulation?-->
      <inertia ixx="0.001" ixy="0" ixz="0" iyy="0.001" iyz="0" izz="0.001"/>
      <!-- To stabilize simulation -->
    </inertial>
    <visual>
      <origin rpy="0 0 0" xyz="0.0065 0 0"/>
      <geometry>
        <box size="0.013 0.002 0.012"/>
      </geometry>
      <material name="Hey5DarkGrey"/>
    </visual>
    <collision>
      <origin rpy="0 0 0" xyz="0 0 0"/>
      <geometry>
        <box size="0.013 0.002 0.012"/>
      </geometry>
    </collision>
  </link>

  <joint name="hand_index_flex_3_joint" type="revolute">
    <parent link="hand_index_virtual_3_link"/>
    <child link="hand_index_flex_3_link"/>
    <origin rpy="0 0 0" xyz="0.013 0 0"/>
    <axis xyz="0 0 1"/>
    <limit effort="2.0" lower="0.0" upper="0.785398163397" velocity="2.0"/>
    <dynamics damping="0.5" friction="0.0"/>
  </joint>
  <link name="hand_index_flex_3_link">
    <inertial>
      <origin rpy="0 0 0" xyz="0.0096 0.003 0.0"/>
      <mass value="0.015"/>
      <inertia ixx="0.001" ixy="0" ixz="0" iyy="0.001" iyz="0" izz="0.001"/>
      <!-- To stabilize simulation -->
    </inertial>
    <visual>
      <origin rpy="0 0 0" xyz="0 0 0"/>
      <geometry>
        <mesh filename="tiago/meshes/finger_flex_tip_collision.stl"/>
      </geometry>
      <material name="Hey5DarkGrey"/>
    </visual>
    <collision>
      <origin rpy="0 0 0" xyz="0 0 0"/>
      <geometry>
        <mesh filename="tiago/meshes/finger_flex_tip_collision.stl"/>
      </geometry>
    </collision>
  </link>

  <joint name="hand_middle_abd_joint" type="fixed">
    <parent link="hand_palm_link"/>
    <child link="hand_middle_abd_link"/>
    <origin rpy="-1.57079632679 0 0" xyz="0.1335 0.0042 0.007"/>
    <axis xyz="0 0 1"/>
    <limit effort="2.0" lower="-0.523598775598" upper="0.523598775598" velocity="2.0"/>
    <dynamics damping="0.5" friction="0.0"/>
  </joint>
  <link name="hand_middle_abd_link">
    <inertial>
      <origin rpy="0 0 0" xyz="-0.0018 0.0 0.0028"/>
      <mass value="0.018"/>
      <inertia ixx="0.001" ixy="0" ixz="0" iyy="0.001" iyz="0" izz="0.001"/>
      <!-- To stabilize simulation -->
    </inertial>
    <visual>
      <origin rpy="0 0 0" xyz="0 0 0"/>
      <geometry>
        <mesh filename="tiago/meshes/finger_abd_collision.stl" scale="1 1 1"/>
      </geometry>
      <material name="Hey5DarkGrey"/>
    </visual>
    <collision>
      <origin rpy="0 0 0" xyz="0 0 0"/>
      <geometry>
        <mesh filename="tiago/meshes/finger_abd_collision.stl" scale="1 1 1"/>
      </geometry>
    </collision>
  </link>

  <joint name="hand_middle_virtual_1_joint" type="revolute">
    <parent link="hand_middle_abd_link"/>
    <child link="hand_middle_virtual_1_link"/>
    <origin rpy="1.57079632679 0 0" xyz="0.009 0 0"/>
    <axis xyz="0 0 1"/>
    <limit effort="2.0" lower="0.0" upper="0.785398163397" velocity="2.0"/>
    <dynamics damping="0.5" friction="0.0"/>
  </joint>
  <link name="hand_middle_virtual_1_link">
    <inertial>
      <origin rpy="0 0 0" xyz="0.0065 0 0"/>
      <mass value="0.01"/>
      <!--TODO: can we make it zero and still have a stable dynamic simulation?-->
      <inertia ixx="0.001" ixy="0" ixz="0" iyy="0.001" iyz="0" izz="0.001"/>
      <!-- To stabilize simulation -->
    </inertial>
    <visual>
      <origin rpy="0 0 0" xyz="0.0065 0 0"/>
      <geometry>
        <box size="0.013 0.002 0.012"/>
      </geometry>
      <material name="Hey5DarkGrey"/>
    </visual>
    <collision>
      <origin rpy="0 0 0" xyz="0 0 0"/>
      <geometry>
        <box size="0.013 0.002 0.012"/>
      </geometry>
    </collision>
  </link>

  <joint name="hand_middle_flex_1_joint" type="revolute">
    <parent link="hand_middle_virtual_1_link"/>
    <child link="hand_middle_flex_1_link"/>
    <origin rpy="0 0 0" xyz="0.013 0 0"/>
    <axis xyz="0 0 1"/>
    <limit effort="2.0" lower="0.0" upper="0.785398163397" velocity="2.0"/>
    <dynamics damping="0.5" friction="0.0"/>
  </joint>
  <link name="hand_middle_flex_1_link">
    <inertial>
      <origin rpy="0 0 0" xyz="0.0047 0.0031 0.0"/>
      <mass value="0.009"/>
      <inertia ixx="0.001" ixy="0" ixz="0" iyy="0.001" iyz="0" izz="0.001"/>
      <!-- To stabilize simulation -->
    </inertial>
    <visual>
      <origin rpy="0 0 0" xyz="0 0 0"/>
      <geometry>
        <mesh filename="tiago/meshes/finger_flex_collision.stl"/>
      </geometry>
      <material name="Hey5DarkGrey"/>
    </visual>
    <collision>
      <origin rpy="0 0 0" xyz="0 0 0"/>
      <geometry>
        <mesh filename="tiago/meshes/finger_flex_collision.stl"/>
      </geometry>
    </collision>
  </link>

  <joint name="hand_middle_virtual_2_joint" type="revolute">
    <parent link="hand_middle_flex_1_link"/>
    <child link="hand_middle_virtual_2_link"/>
    <origin rpy="0 0 0" xyz="0.009 0 0"/>
    <axis xyz="0 0 1"/>
    <limit effort="2.0" lower="0.0" upper="0.785398163397" velocity="2.0"/>
    <dynamics damping="0.5" friction="0.0"/>
  </joint>
  <link name="hand_middle_virtual_2_link">
    <inertial>
      <origin rpy="0 0 0" xyz="0.0065 0 0"/>
      <mass value="0.01"/>
      <!--TODO: can we make it zero and still have a stable dynamic simulation?-->
      <inertia ixx="0.001" ixy="0" ixz="0" iyy="0.001" iyz="0" izz="0.001"/>
      <!-- To stabilize simulation -->
    </inertial>
    <visual>
      <origin rpy="0 0 0" xyz="0.0065 0 0"/>
      <geometry>
        <box size="0.013 0.002 0.012"/>
      </geometry>
      <material name="Hey5DarkGrey"/>
    </visual>
    <collision>
      <origin rpy="0 0 0" xyz="0 0 0"/>
      <geometry>
        <box size="0.013 0.002 0.012"/>
      </geometry>
    </collision>
  </link>

  <joint name="hand_middle_flex_2_joint" type="revolute">
    <parent link="hand_middle_virtual_2_link"/>
    <child link="hand_middle_flex_2_link"/>
    <origin rpy="0 0 0" xyz="0.013 0 0"/>
    <axis xyz="0 0 1"/>
    <limit effort="2.0" lower="0.0" upper="0.785398163397" velocity="2.0"/>
    <dynamics damping="0.5" friction="0.0"/>
  </joint>
  <link name="hand_middle_flex_2_link">
    <inertial>
      <origin rpy="0 0 0" xyz="0.0047 0.0031 0.0"/>
      <mass value="0.009"/>
      <inertia ixx="0.001" ixy="0" ixz="0" iyy="0.001" iyz="0" izz="0.001"/>
      <!-- To stabilize simulation -->
    </inertial>
    <visual>
      <origin rpy="0 0 0" xyz="0 0 0"/>
      <geometry>
        <mesh filename="tiago/meshes/finger_flex_collision.stl"/>
      </geometry>
      <material name="Hey5DarkGrey"/>
    </visual>
    <collision>
      <origin rpy="0 0 0" xyz="0 0 0"/>
      <geometry>
        <mesh filename="tiago/meshes/finger_flex_collision.stl"/>
      </geometry>
    </collision>
  </link>

  <joint name="hand_middle_virtual_3_joint" type="revolute">
    <parent link="hand_middle_flex_2_link"/>
    <child link="hand_middle_virtual_3_link"/>
    <origin rpy="0 0 0" xyz="0.009 0 0"/>
    <axis xyz="0 0 1"/>
    <limit effort="2.0" lower="0.0" upper="0.785398163397" velocity="2.0"/>
    <dynamics damping="0.5" friction="0.0"/>
  </joint>
  <link name="hand_middle_virtual_3_link">
    <inertial>
      <origin rpy="0 0 0" xyz="0.0065 0 0"/>
      <mass value="0.01"/>
      <!--TODO: can we make it zero and still have a stable dynamic simulation?-->
      <inertia ixx="0.001" ixy="0" ixz="0" iyy="0.001" iyz="0" izz="0.001"/>
      <!-- To stabilize simulation -->
    </inertial>
    <visual>
      <origin rpy="0 0 0" xyz="0.0065 0 0"/>
      <geometry>
        <box size="0.013 0.002 0.012"/>
      </geometry>
      <material name="Hey5DarkGrey"/>
    </visual>
    <collision>
      <origin rpy="0 0 0" xyz="0 0 0"/>
      <geometry>
        <box size="0.013 0.002 0.012"/>
      </geometry>
    </collision>
  </link>

  <joint name="hand_middle_flex_3_joint" type="revolute">
    <parent link="hand_middle_virtual_3_link"/>
    <child link="hand_middle_flex_3_link"/>
    <origin rpy="0 0 0" xyz="0.013 0 0"/>
    <axis xyz="0 0 1"/>
    <limit effort="2.0" lower="0.0" upper="0.785398163397" velocity="2.0"/>
    <dynamics damping="0.5" friction="0.0"/>
  </joint>
  <link name="hand_middle_flex_3_link">
    <inertial>
      <origin rpy="0 0 0" xyz="0.0096 0.003 0.0"/>
      <mass value="0.015"/>
      <inertia ixx="0.001" ixy="0" ixz="0" iyy="0.001" iyz="0" izz="0.001"/>
      <!-- To stabilize simulation -->
    </inertial>
    <visual>
      <origin rpy="0 0 0" xyz="0 0 0"/>
      <geometry>
        <mesh filename="tiago/meshes/finger_flex_tip_collision.stl"/>
      </geometry>
      <material name="Hey5DarkGrey"/>
    </visual>
    <collision>
      <origin rpy="0 0 0" xyz="0 0 0"/>
      <geometry>
        <mesh filename="tiago/meshes/finger_flex_tip_collision.stl"/>
      </geometry>
    </collision>
  </link>

  <joint name="hand_ring_abd_joint" type="fixed">
    <parent link="hand_palm_link"/>
    <child link="hand_ring_abd_link"/>
    <origin rpy="-1.57079632679 0.261799387799 0" xyz="0.1265 0.0042 -0.0125"/>
    <axis xyz="0 0 1"/>
    <limit effort="2.0" lower="-0.523598775598" upper="0.523598775598" velocity="2.0"/>
    <dynamics damping="0.5" friction="0.0"/>
  </joint>
  <link name="hand_ring_abd_link">
    <inertial>
      <origin rpy="0 0 0" xyz="-0.0018 0.0 0.0028"/>
      <mass value="0.018"/>
      <inertia ixx="0.001" ixy="0" ixz="0" iyy="0.001" iyz="0" izz="0.001"/>
      <!-- To stabilize simulation -->
    </inertial>
    <visual>
      <origin rpy="0 0 0" xyz="0 0 0"/>
      <geometry>
        <mesh filename="tiago/meshes/finger_abd_collision.stl" scale="1 1 1"/>
      </geometry>
      <material name="Hey5DarkGrey"/>
    </visual>
    <collision>
      <origin rpy="0 0 0" xyz="0 0 0"/>
      <geometry>
        <mesh filename="tiago/meshes/finger_abd_collision.stl" scale="1 1 1"/>
      </geometry>
    </collision>
  </link>

  <joint name="hand_ring_virtual_1_joint" type="revolute">
    <parent link="hand_ring_abd_link"/>
    <child link="hand_ring_virtual_1_link"/>
    <origin rpy="1.57079632679 0 0" xyz="0.009 0 0"/>
    <axis xyz="0 0 1"/>
    <limit effort="2.0" lower="0.0" upper="0.785398163397" velocity="2.0"/>
    <dynamics damping="0.5" friction="0.0"/>
  </joint>
  <link name="hand_ring_virtual_1_link">
    <inertial>
      <origin rpy="0 0 0" xyz="0.0065 0 0"/>
      <mass value="0.01"/>
      <!--TODO: can we make it zero and still have a stable dynamic simulation?-->
      <inertia ixx="0.001" ixy="0" ixz="0" iyy="0.001" iyz="0" izz="0.001"/>
      <!-- To stabilize simulation -->
    </inertial>
    <visual>
      <origin rpy="0 0 0" xyz="0.0065 0 0"/>
      <geometry>
        <box size="0.013 0.002 0.012"/>
      </geometry>
      <material name="Hey5DarkGrey"/>
    </visual>
    <collision>
      <origin rpy="0 0 0" xyz="0 0 0"/>
      <geometry>
        <box size="0.013 0.002 0.012"/>
      </geometry>
    </collision>
  </link>

  <joint name="hand_ring_flex_1_joint" type="revolute">
    <parent link="hand_ring_virtual_1_link"/>
    <child link="hand_ring_flex_1_link"/>
    <origin rpy="0 0 0" xyz="0.013 0 0"/>
    <axis xyz="0 0 1"/>
    <limit effort="2.0" lower="0.0" upper="0.785398163397" velocity="2.0"/>
    <dynamics damping="0.5" friction="0.0"/>
  </joint>
  <link name="hand_ring_flex_1_link">
    <inertial>tiago/meshes
      <origin rpy="0 0 0" xyz="0.0047 0.0031 0.0"/>
      <mass value="0.009"/>
      <inertia ixx="0.001" ixy="0" ixz="0" iyy="0.001" iyz="0" izz="0.001"/>
      <!-- To stabilize simulation -->
    </inertial>
    <visual>
      <origin rpy="0 0 0" xyz="0 0 0"/>
      <geometry>
        <mesh filename="tiago/meshes/finger_flex_collision.stl"/>
      </geometry>
      <material name="Hey5DarkGrey"/>
    </visual>
    <collision>
      <origin rpy="0 0 0" xyz="0 0 0"/>
      <geometry>
        <mesh filename="tiago/meshes/finger_flex_collision.stl"/>
      </geometry>
    </collision>
  </link>

  <joint name="hand_ring_virtual_2_joint" type="revolute">
    <parent link="hand_ring_flex_1_link"/>
    <child link="hand_ring_virtual_2_link"/>
    <origin rpy="0 0 0" xyz="0.009 0 0"/>
    <axis xyz="0 0 1"/>
    <limit effort="2.0" lower="0.0" upper="0.785398163397" velocity="2.0"/>
    <dynamics damping="0.5" friction="0.0"/>
  </joint>
  <link name="hand_ring_virtual_2_link">
    <inertial>
      <origin rpy="0 0 0" xyz="0.0065 0 0"/>
      <mass value="0.01"/>
      <!--TODO: can we make it zero and still have a stable dynamic simulation?-->
      <inertia ixx="0.001" ixy="0" ixz="0" iyy="0.001" iyz="0" izz="0.001"/>
      <!-- To stabilize simulation -->
    </inertial>
    <visual>
      <origin rpy="0 0 0" xyz="0.0065 0 0"/>
      <geometry>
        <box size="0.013 0.002 0.012"/>
      </geometry>
      <material name="Hey5DarkGrey"/>
    </visual>
    <collision>
      <origin rpy="0 0 0" xyz="0 0 0"/>
      <geometry>
        <box size="0.013 0.002 0.012"/>
      </geometry>
    </collision>
  </link>

  <joint name="hand_ring_flex_2_joint" type="revolute">
    <parent link="hand_ring_virtual_2_link"/>
    <child link="hand_ring_flex_2_link"/>
    <origin rpy="0 0 0" xyz="0.013 0 0"/>
    <axis xyz="0 0 1"/>
    <limit effort="2.0" lower="0.0" upper="0.785398163397" velocity="2.0"/>
    <dynamics damping="0.5" friction="0.0"/>
  </joint>
  <link name="hand_ring_flex_2_link">
    <inertial>
      <origin rpy="0 0 0" xyz="0.0047 0.0031 0.0"/>
      <mass value="0.009"/>
      <inertia ixx="0.001" ixy="0" ixz="0" iyy="0.001" iyz="0" izz="0.001"/>
      <!-- To stabilize simulation -->
    </inertial>
    <visual>
      <origin rpy="0 0 0" xyz="0 0 0"/>
      <geometry>
        <mesh filename="tiago/meshes/finger_flex_collision.stl"/>
      </geometry>
      <material name="Hey5DarkGrey"/>
    </visual>
    <collision>
      <origin rpy="0 0 0" xyz="0 0 0"/>
      <geometry>
        <mesh filename="tiago/meshes/finger_flex_collision.stl"/>
      </geometry>
    </collision>
  </link>

  <joint name="hand_ring_virtual_3_joint" type="revolute">
    <parent link="hand_ring_flex_2_link"/>
    <child link="hand_ring_virtual_3_link"/>
    <origin rpy="0 0 0" xyz="0.009 0 0"/>
    <axis xyz="0 0 1"/>
    <limit effort="2.0" lower="0.0" upper="0.785398163397" velocity="2.0"/>
    <dynamics damping="0.5" friction="0.0"/>
  </joint>
  <link name="hand_ring_virtual_3_link">
    <inertial>
      <origin rpy="0 0 0" xyz="0.0065 0 0"/>
      <mass value="0.01"/>
      <!--TODO: can we make it zero and still have a stable dynamic simulation?-->
      <inertia ixx="0.001" ixy="0" ixz="0" iyy="0.001" iyz="0" izz="0.001"/>
      <!-- To stabilize simulation -->
    </inertial>
    <visual>
      <origin rpy="0 0 0" xyz="0.0065 0 0"/>
      <geometry>
        <box size="0.013 0.002 0.012"/>
      </geometry>
      <material name="Hey5DarkGrey"/>
    </visual>
    <collision>
      <origin rpy="0 0 0" xyz="0 0 0"/>
      <geometry>
        <box size="0.013 0.002 0.012"/>
      </geometry>
    </collision>
  </link>

  <joint name="hand_ring_flex_3_joint" type="revolute">
    <parent link="hand_ring_virtual_3_link"/>
    <child link="hand_ring_flex_3_link"/>
    <origin rpy="0 0 0" xyz="0.013 0 0"/>
    <axis xyz="0 0 1"/>
    <limit effort="2.0" lower="0.0" upper="0.785398163397" velocity="2.0"/>
    <dynamics damping="0.5" friction="0.0"/>
  </joint>
  <link name="hand_ring_flex_3_link">
    <inertial>
      <origin rpy="0 0 0" xyz="0.0096 0.003 0.0"/>
      <mass value="0.015"/>
      <inertia ixx="0.001" ixy="0" ixz="0" iyy="0.001" iyz="0" izz="0.001"/>
      <!-- To stabilize simulation -->
    </inertial>
    <visual>
      <origin rpy="0 0 0" xyz="0 0 0"/>
      <geometry>
        <mesh filename="tiago/meshes/finger_flex_tip_collision.stl"/>
      </geometry>
      <material name="Hey5DarkGrey"/>
    </visual>
    <collision>
      <origin rpy="0 0 0" xyz="0 0 0"/>
      <geometry>
        <mesh filename="tiago/meshes/finger_flex_tip_collision.stl"/>
      </geometry>
    </collision>
  </link>

  <joint name="hand_little_abd_joint" type="fixed">
    <parent link="hand_palm_link"/>
    <child link="hand_little_abd_link"/>
    <origin rpy="-1.57079632679 0.523598775598 0" xyz="0.1165 0.0042 -0.032"/>
    <axis xyz="0 0 1"/>
    <limit effort="2.0" lower="-0.523598775598" upper="0.523598775598" velocity="2.0"/>
    <dynamics damping="0.5" friction="0.0"/>
  </joint>
  <link name="hand_little_abd_link">
    <inertial>
      <origin rpy="0 0 0" xyz="-0.0018 0.0 0.0028"/>
      <mass value="0.018"/>
      <inertia ixx="0.001" ixy="0" ixz="0" iyy="0.001" iyz="0" izz="0.001"/>
      <!-- To stabilize simulation -->
    </inertial>
    <visual>
      <origin rpy="0 0 0" xyz="0 0 0"/>
      <geometry>
        <mesh filename="tiago/meshes/finger_abd_collision.stl" scale="1 1 1"/>
      </geometry>
      <material name="Hey5DarkGrey"/>
    </visual>
    <collision>
      <origin rpy="0 0 0" xyz="0 0 0"/>
      <geometry>
        <mesh filename="tiago/meshes/finger_abd_collision.stl" scale="1 1 1"/>
      </geometry>
    </collision>
  </link>

  <joint name="hand_little_virtual_1_joint" type="revolute">
    <parent link="hand_little_abd_link"/>
    <child link="hand_little_virtual_1_link"/>
    <origin rpy="1.57079632679 0 0" xyz="0.009 0 0"/>
    <axis xyz="0 0 1"/>
    <limit effort="2.0" lower="0.0" upper="0.785398163397" velocity="2.0"/>
    <dynamics damping="0.5" friction="0.0"/>
  </joint>
  <link name="hand_little_virtual_1_link">
    <inertial>
      <origin rpy="0 0 0" xyz="0.0065 0 0"/>
      <mass value="0.01"/>
      <!--TODO: can we make it zero and still have a stable dynamic simulation?-->
      <inertia ixx="0.001" ixy="0" ixz="0" iyy="0.001" iyz="0" izz="0.001"/>
      <!-- To stabilize simulation -->
    </inertial>
    <visual>
      <origin rpy="0 0 0" xyz="0.0065 0 0"/>
      <geometry>
        <box size="0.013 0.002 0.012"/>
      </geometry>
      <material name="Hey5DarkGrey"/>
    </visual>
    <collision>
      <origin rpy="0 0 0" xyz="0 0 0"/>
      <geometry>
        <box size="0.013 0.002 0.012"/>
      </geometry>
    </collision>
  </link>

  <joint name="hand_little_flex_1_joint" type="revolute">
    <parent link="hand_little_virtual_1_link"/>
    <child link="hand_little_flex_1_link"/>
    <origin rpy="0 0 0" xyz="0.013 0 0"/>
    <axis xyz="0 0 1"/>
    <limit effort="2.0" lower="0.0" upper="0.785398163397" velocity="2.0"/>
    <dynamics damping="0.5" friction="0.0"/>
  </joint>
  <link name="hand_little_flex_1_link">
    <inertial>
      <origin rpy="0 0 0" xyz="0.0047 0.0031 0.0"/>
      <mass value="0.009"/>
      <inertia ixx="0.001" ixy="0" ixz="0" iyy="0.001" iyz="0" izz="0.001"/>
      <!-- To stabilize simulation -->
    </inertial>
    <visual>
      <origin rpy="0 0 0" xyz="0 0 0"/>
      <geometry>
        <mesh filename="tiago/meshes/finger_flex_collision.stl"/>
      </geometry>
      <material name="Hey5DarkGrey"/>
    </visual>
    <collision>
      <origin rpy="0 0 0" xyz="0 0 0"/>
      <geometry>
        <mesh filename="tiago/meshes/finger_flex_collision.stl"/>
      </geometry>
    </collision>
  </link>

  <joint name="hand_little_virtual_2_joint" type="revolute">
    <parent link="hand_little_flex_1_link"/>
    <child link="hand_little_virtual_2_link"/>
    <origin rpy="0 0 0" xyz="0.009 0 0"/>
    <axis xyz="0 0 1"/>
    <limit effort="2.0" lower="0.0" upper="0.785398163397" velocity="2.0"/>
    <dynamics damping="0.5" friction="0.0"/>
  </joint>
  <link name="hand_little_virtual_2_link">
    <inertial>
      <origin rpy="0 0 0" xyz="0.0065 0 0"/>
      <mass value="0.01"/>
      <!--TODO: can we make it zero and still have a stable dynamic simulation?-->
      <inertia ixx="0.001" ixy="0" ixz="0" iyy="0.001" iyz="0" izz="0.001"/>
      <!-- To stabilize simulation -->
    </inertial>
    <visual>
      <origin rpy="0 0 0" xyz="0.0065 0 0"/>
      <geometry>
        <box size="0.013 0.002 0.012"/>
      </geometry>
      <material name="Hey5DarkGrey"/>
    </visual>
    <collision>
      <origin rpy="0 0 0" xyz="0 0 0"/>
      <geometry>
        <box size="0.013 0.002 0.012"/>
      </geometry>
    </collision>
  </link>

  <joint name="hand_little_flex_2_joint" type="revolute">
    <parent link="hand_little_virtual_2_link"/>
    <child link="hand_little_flex_2_link"/>
    <origin rpy="0 0 0" xyz="0.013 0 0"/>
    <axis xyz="0 0 1"/>
    <limit effort="2.0" lower="0.0" upper="0.785398163397" velocity="2.0"/>
    <dynamics damping="0.5" friction="0.0"/>
  </joint>
  <link name="hand_little_flex_2_link">
    <inertial>
      <origin rpy="0 0 0" xyz="0.0047 0.0031 0.0"/>
      <mass value="0.009"/>
      <inertia ixx="0.001" ixy="0" ixz="0" iyy="0.001" iyz="0" izz="0.001"/>
      <!-- To stabilize simulation -->
    </inertial>
    <visual>
      <origin rpy="0 0 0" xyz="0 0 0"/>
      <geometry>
        <mesh filename="tiago/meshes/finger_flex_collision.stl"/>
      </geometry>
      <material name="Hey5DarkGrey"/>
    </visual>
    <collision>
      <origin rpy="0 0 0" xyz="0 0 0"/>
      <geometry>
        <mesh filename="tiago/meshes/finger_flex_collision.stl"/>
      </geometry>
    </collision>
  </link>

  <joint name="hand_little_virtual_3_joint" type="revolute">
    <parent link="hand_little_flex_2_link"/>
    <child link="hand_little_virtual_3_link"/>
    <origin rpy="0 0 0" xyz="0.009 0 0"/>
    <axis xyz="0 0 1"/>
    <limit effort="2.0" lower="0.0" upper="0.785398163397" velocity="2.0"/>
    <dynamics damping="0.5" friction="0.0"/>
  </joint>
  <link name="hand_little_virtual_3_link">
    <inertial>
      <origin rpy="0 0 0" xyz="0.0065 0 0"/>
      <mass value="0.01"/>
      <!--TODO: can we make it zero and still have a stable dynamic simulation?-->
      <inertia ixx="0.001" ixy="0" ixz="0" iyy="0.001" iyz="0" izz="0.001"/>
      <!-- To stabilize simulation -->
    </inertial>
    <visual>
      <origin rpy="0 0 0" xyz="0.0065 0 0"/>
      <geometry>
        <box size="0.013 0.002 0.012"/>
      </geometry>
      <material name="Hey5DarkGrey"/>
    </visual>
    <collision>
      <origin rpy="0 0 0" xyz="0 0 0"/>
      <geometry>
        <box size="0.013 0.002 0.012"/>
      </geometry>
    </collision>
  </link>

  <joint name="hand_little_flex_3_joint" type="revolute">
    <parent link="hand_little_virtual_3_link"/>
    <child link="hand_little_flex_3_link"/>
    <origin rpy="0 0 0" xyz="0.013 0 0"/>
    <axis xyz="0 0 1"/>
    <limit effort="2.0" lower="0.0" upper="0.785398163397" velocity="2.0"/>
    <dynamics damping="0.5" friction="0.0"/>
  </joint>
  <link name="hand_little_flex_3_link">
    <inertial>
      <origin rpy="0 0 0" xyz="0.0096 0.003 0.0"/>
      <mass value="0.015"/>
      <inertia ixx="0.001" ixy="0" ixz="0" iyy="0.001" iyz="0" izz="0.001"/>
      <!-- To stabilize simulation -->
    </inertial>
    <visual>
      <origin rpy="0 0 0" xyz="0 0 0"/>
      <geometry>
        <mesh filename="tiago/meshes/finger_flex_tip_collision.stl"/>
      </geometry>
      <material name="Hey5DarkGrey"/>
    </visual>
    <collision>
      <origin rpy="0 0 0" xyz="0 0 0"/>
      <geometry>
        <mesh filename="tiago/meshes/finger_flex_tip_collision.stl"/>
      </geometry>
    </collision>
  </link>



</robot>
