<?xml version="1.0" ?>
<!-- =================================================================================== -->
<!-- |    This document was autogenerated by xacro from tiago_titanium111.urdf.xacro   | -->
<!-- |    EDITING THIS FILE BY HAND IS NOT RECOMMENDED                                 | -->
<!-- =================================================================================== -->
<!--
  Copyright (c) 2011, PAL Robotics, S.L.
  All rights reserved.

  This work is licensed under the Creative Commons Attribution-NonCommercial-NoDerivs 3.0 Unported License.
  To view a copy of this license, visit http://creativecommons.org/licenses/by-nc-nd/3.0/ or send a letter to
  Creative Commons, 444 Castro Street, Suite 900, Mountain View, California, 94041, USA.
-->
<robot name="tiago" xmlns:xacro="http://www.ros.org/wiki/xacro">

  <!-- Base -->
  <link name="base_link">
    <inertial>
      <mass value="28.26649"/>
      <inertia ixx="0.46
        5" ixy="0.002" ixz="-0.001" iyy="0.483" iyz="0" izz="0.55093970"/>
    </inertial>
    <visual>
      <geometry>
        <mesh filename="tiago/meshes/base/base.stl"/>
      </geometry>
      <material name="White"/>
    </visual>
    <collision>
      <geometry>
        <mesh filename="tiago/meshes/base/base_collision.dae"/>
      </geometry>
      <material name="White"/>
    </collision>
  </link>

  <link name="wheel_right_link">
    <inertial>
      <origin  xyz="0 0 -0.00207"/>
      <mass value="1.82362"/>
      <inertia ixx="0.004" ixy="0" ixz="-0" iyy="0.004" iyz="0" izz="0"/>
    </inertial>
    <visual>
      <geometry>
        <mesh filename="tiago/meshes/wheels/wheel.stl"/>
      </geometry>
      <material name="DarkGrey"/>
    </visual>
    <collision>
      <geometry>
        <cylinder length="0.04" radius="0.0985"/>
      </geometry>
    </collision>
  </link>
  <joint name="wheel_right_joint" type="fixed">
    <parent link="base_link"/>
    <child link="wheel_right_link"/>
    <origin rpy="-1.57 0 0" xyz="0 -0.2022 0"/>
    <axis xyz="0 0 1"/>
    <limit effort="6.0" lower="-3.14" upper="3.14" velocity="10"/>
  </joint>

  <!-- Contact model for the wheel surface -->

  <link name="wheel_left_link">
    <inertial>
      <origin xyz="0 0 0.00207"/>
      <mass value="1.82362"/>
      <inertia ixx="0.004" ixy="-0.0" ixz="-0.0" iyy="0.004" iyz="0.0" izz="0.008"/>
    </inertial>
    <visual>
      <origin rpy="-3.14 0 0"/>
      <geometry>
        <mesh filename="tiago/meshes/wheels/wheel.stl"/>
      </geometry>
      <material name="DarkGrey"/>
    </visual>
    <collision>
      <geometry>
        <cylinder length="0.04" radius="0.0985"/>
      </geometry>
    </collision>
  </link>
  <joint name="wheel_left_joint" type="fixed">
    <parent link="base_link"/>
    <child link="wheel_left_link"/>
    <origin rpy="-1.57 0 0" xyz="0 0.2022 0"/>
    <axis xyz="0 0 1"/>
    <limit effort="6.0" lower="-3.14" upper="3.14" velocity="10"/>
  </joint>
  <!-- Bottom fixed part of column -->
  <link name="torso_fixed_link">
    <inertial>
      <origin  xyz="0.02435 -0.00464 0.15900"/>
      <mass value="14.01360"/>
      <inertia ixx="0.38341100000" ixy="0.00036400000" ixz="-0.02438900000" iyy="0.40577300000" iyz="-0.00078200000" izz="0.07699800000"/>
    </inertial>
    <visual>
      <geometry>
        <mesh filename="tiago/meshes/torso/torso_fix.stl" scale="1 1 1"/>
      </geometry>
      <material name="LightGrey"/>
    </visual>
    <collision>
      <origin xyz="0.085 0.0 0.02"/>
      <geometry>
        <box size="0.4 0.25 0.04"/>
      </geometry>
    </collision>
    <collision>
      <origin  xyz="0 0 0.05"/>
      <geometry>
        <box size="0.25 0.25 0.1"/>
      </geometry>
    </collision>
  </link>
  <joint name="torso_fixed_joint" type="fixed">
    <origin  xyz="-0.062 0.0 0.193"/>
    <parent link="base_link"/>
    <child link="torso_fixed_link"/>
  </joint>


  <link name="torso_lift_link">
    <inertial>
      <origin  xyz="0.04361 -0.00116 -0.17334"/>
      <mass value="6.93198"/>
      <inertia ixx="0.24487000000" ixy="-0.00145600000" ixz="-0.00974200000" iyy="0.24926900000" iyz="0.00828100000" izz="0.09039500000"/>
    </inertial>
    <!-- Lifting body -->
    <visual>
      <geometry>
        <mesh filename="tiago/meshes/torso/torso_lift_with_arm.stl" scale="1 1 1"/>
      </geometry>
      <material name="White"/>
    </visual>
    <collision>
      <geometry>
        <mesh filename="tiago/meshes/torso/torso_lift_collision.dae" scale="1 1 1"/>
      </geometry>
      <material name="LightGrey"/>
    </collision>
  </link>
  <joint name="torso_lift_joint" type="fixed">
    <origin xyz="0.0 0.0 0.772"/>
    <parent link="torso_fixed_link"/>
    <child link="torso_lift_link"/>
    <axis xyz="0 0 1"/>
    <limit effort="2000" lower="0" upper="0.35" velocity="0.07"/>
    <calibration rising="0.0"/>
    <dynamics damping="1000"/>
    <safety_controller k_position="20" k_velocity="20" soft_lower_limit="0.0" soft_upper_limit="0.35"/>
  </joint>

  <link name="head_1_link">
    <inertial>
      <origin rpy="0.00000 0.00000 0.00000" xyz="-0.00508 0.00237 0.07229"/>
      <mass value="0.62220"/>
      <inertia ixx="0.00119200000" ixy="-0.00000700000" ixz="0.00009600000" iyy="0.00140200000" iyz="0.00000400000" izz="0.00088900000"/>
    </inertial>
    <visual>
      <origin rpy="0 0 0" xyz="0 0 0"/>
      <geometry>
        <mesh filename="tiago/meshes/head/head_1.stl" scale="1 1 1"/>
      </geometry>
      <material name="White"/>
    </visual>
    <collision>
      <origin rpy="0 0 0.0" xyz="0.0 0 0"/>
      <geometry>
        <mesh filename="tiago/meshes/head/head_1_collision.dae" scale="1 1 1"/>
      </geometry>
      <material name="White"/>
    </collision>
  </link>
  <joint name="head_1_joint" type="revolute">
    <parent link="torso_lift_link"/>
    <child link="head_1_link"/>
    <origin rpy="0 0 0" xyz="0.182 0.0 0.0"/>
    <axis xyz="0 0 1"/>
    <limit effort="5.197" lower="-1.308996939" upper="1.308996939" velocity="3.0"/>
    <dynamics damping="0.5" friction="1.0"/>
    <safety_controller k_position="20" k_velocity="20" soft_lower_limit="-1.288996939" soft_upper_limit="1.288996939"/>
  </joint>



  <link name="head_2_link">
    <inertial>
      <origin rpy="0.00000 0.00000 0.00000" xyz="0.04700 0.05542 0.00022"/>
      <mass value="0.66123"/>
      <inertia ixx="0.00462000000" ixy="0.00068900000" ixz="0.00000600000" iyy="0.00486100000" iyz="0.00000600000" izz="0.00313200000"/>
    </inertial>
    <visual>
      <origin rpy="0 0 0" xyz="0 0 0"/>
      <geometry>
        <mesh filename="tiago/meshes/head/head_2.stl" scale="1 1 1"/>
      </geometry>
      <material name="White"/>
    </visual>
    <collision>
      <origin rpy="0 0 0" xyz="0 0 0"/>
      <geometry>
        <mesh filename="tiago/meshes/head/head_2_collision.dae" scale="1 1 1"/>
      </geometry>
    </collision>
  </link>
  <joint name="head_2_joint" type="revolute">
    <parent link="head_1_link"/>
    <child link="head_2_link"/>
    <origin rpy="1.57079632679 0 0" xyz="0.005 0.0 0.098"/>
    <axis xyz="0 0 1"/>
    <limit effort="2.77" lower="-1.0471975512" upper="0.785398163397" velocity="3.0"/>
    <dynamics damping="0.5" friction="1.0"/>
    <safety_controller k_position="20" k_velocity="20" soft_lower_limit="-1.0271975512" soft_upper_limit="0.785398163397"/>
  </joint>



  <!--************************-->
  <!--        SHOULDER        -->
  <!--************************-->
  <link name="arm_1_link">
    <inertial>
      <origin rpy="0.00000 0.00000 0.00000" xyz="0.08169 0.01822 -0.01884"/>
      <mass value="2.31325"/>
      <inertia ixx="0.00269400000" ixy="0.00115700000" ixz="-0.00142300000" iyy="0.00704100000" iyz="-0.00031200000" izz="0.00731200000"/>
    </inertial>
    <!-- M90 module -->
    <visual>
      <origin rpy="0 0 0" xyz="0 0 0"/>
      <geometry>
        <mesh filename="tiago/meshes/arm/arm_1.stl" scale="1 1 1"/>
      </geometry>
      <material name="White"/>
    </visual>
    <collision>
      <origin rpy="0 0 0" xyz="0 0 0"/>
      <geometry>
        <mesh filename="tiago/meshes/arm/arm_1_collision.dae" scale="1 1 1"/>
      </geometry>
    </collision>
  </link>

  <joint name="arm_1_joint" type="revolute">
    <parent link="torso_lift_link"/>
    <child link="arm_1_link"/>
    <origin rpy="0 0 -1.57079632679" xyz="0.15505 0.014 -0.151"/>
    <axis xyz="0 0 1"/>
    <limit effort="39.0" lower="0.0" upper="2.74889357189" velocity="2.7"/>
    <dynamics damping="1.0" friction="1.0"/>
    <safety_controller k_position="20" k_velocity="20" soft_lower_limit="0.02" soft_upper_limit="2.72889357189"/>
  </joint>
  <link name="arm_2_link">
    <inertial>
      <origin rpy="0.00000 0.00000 0.00000" xyz="-0.03609 -0.00006 0.01649"/>
      <mass value="1.10224"/>
      <inertia ixx="0.00114600000" ixy="0.00000100000" ixz="0.00043500000" iyy="0.00218200000" iyz="-0.00000100000" izz="0.00237300000"/>
    </inertial>
    <visual>
      <!-- <origin xyz="0 0 0" rpy="${180 * deg_to_rad} ${0 * deg_to_rad} ${-90 * deg_to_rad}" /> -->
      <origin rpy="0.0 0.0 0.0" xyz="0 0 0"/>
      <geometry>
        <mesh filename="tiago/meshes/arm/arm_2.stl" scale="1 1 1"/>
      </geometry>
      <material name="DarkGrey"/>
    </visual>
    <collision>
      <!-- <origin xyz="0 0 0" rpy="${180 * deg_to_rad} ${0 * deg_to_rad} ${-90 * deg_to_rad}" /> -->
      <origin rpy="0.0 0.0 0.0" xyz="0 0 0"/>
      <geometry>
        <mesh filename="tiago/meshes/arm/arm_2_collision.dae" scale="1 1 1"/>
      </geometry>
    </collision>
  </link>
  <joint name="arm_2_joint" type="revolute">
    <parent link="arm_1_link"/>
    <child link="arm_2_link"/>
    <origin rpy="1.57079632679 0.0 0.0" xyz="0.125 0.0165 -0.031"/>
    <axis xyz="0 0 1"/>
    <limit effort="39.0" lower="-1.57079632679" upper="1.0908307825" velocity="3.66"/>
    <dynamics damping="1.0" friction="1.0"/>
    <safety_controller k_position="20" k_velocity="20" soft_lower_limit="-1.55079632679" soft_upper_limit="1.0708307825"/>
  </joint>
  <link name="arm_3_link">
    <inertial>
      <origin rpy="0.00000 0.00000 0.00000" xyz="0.00752 0.00244 0.12957"/>
      <mass value="2.42460"/>
      <inertia ixx="0.01441800000" ixy="0.00008400000" ixz="0.00114300000" iyy="0.01478800000" iyz="0.00064200000" izz="0.00256000000"/>
    </inertial>
    <visual>
      <origin rpy="0 0 0" xyz="0 0 0"/>
      <geometry>
        <mesh filename="tiago/meshes/arm/arm_3.stl" scale="1 1 1"/>
      </geometry>
      <material name="DarkGrey"/>
    </visual>
    <collision>
      <origin rpy="0 0 0" xyz="0 0 0"/>
      <geometry>
        <mesh filename="tiago/meshes/arm/arm_3_collision.dae" scale="1 1 1"/>
      </geometry>
    </collision>
  </link>
  <joint name="arm_3_joint" type="revolute">
    <parent link="arm_2_link"/>
    <child link="arm_3_link"/>
    <origin rpy="-1.57079632679 0.0 1.57079632679" xyz="0.0895 0.0 0.0015"/>
    <axis xyz="0 0 1"/>
    <limit effort="17.86" lower="-3.53429173529" upper="1.57079632679" velocity="4.58"/>
    <dynamics damping="1.0" friction="1.0"/>
    <safety_controller k_position="20" k_velocity="20" soft_lower_limit="-3.51429173529" soft_upper_limit="1.55079632679"/>
  </joint>
  <!--************************-->
  <!--        ELBOW           -->
  <!--************************-->
  <link name="arm_4_link">
    <inertial>
      <origin rpy="0.00000 0.00000 0.00000" xyz="0.07426 -0.01306 0.01549"/>
      <mass value="1.45429"/>
      <inertia ixx="0.00195300000" ixy="-0.00059600000" ixz="0.00088000000" iyy="0.00709700000" iyz="-0.00017100000" izz="0.00740500000"/>
    </inertial>
    <visual>
      <origin rpy="0 0 0" xyz="0 0 0"/>
      <geometry>
        <mesh filename="tiago/meshes/arm/arm_4.stl" scale="1 1 1"/>
      </geometry>
      <material name="DarkGrey"/>
    </visual>
    <collision>
      <origin rpy="0 0 0" xyz="0 0 0"/>
      <geometry>
        <mesh filename="tiago/meshes/arm/arm_4_collision.dae" scale="1 1 1"/>
      </geometry>
    </collision>
  </link>
  <joint name="arm_4_joint" type="revolute">
    <parent link="arm_3_link"/>
    <child link="arm_4_link"/>
    <origin rpy="-1.57079632679 -1.57079632679 0.0" xyz="-0.02 -0.027 -0.222"/>
    <axis xyz="0 0 1"/>
    <limit effort="17.86" lower="-0.392699081699" upper="2.35619449019" velocity="4.58"/>
    <dynamics damping="1.0" friction="1.0"/>
    <safety_controller k_position="20" k_velocity="20" soft_lower_limit="-0.372699081699" soft_upper_limit="2.33619449019"/>
  </joint>

  <!--************************-->
  <!--        WRIST           -->
  <!--************************-->
  <link name="arm_5_link">
    <inertial>
      <origin rpy="0.00000 0.00000 0.00000" xyz="0.00003 -0.00028 0.07831"/>
      <mass value="1.07424"/>
      <inertia ixx="0.00168000000" ixy="0.00000100000" ixz="-0.00001500000" iyy="0.00160300000" iyz="-0.00001900000" izz="0.00040400000"/>
    </inertial>
    <visual>
      <origin rpy="0 0 0" xyz="0 0 0"/>
      <geometry>
        <mesh filename="tiago/meshes/arm/arm_5.stl" scale="1 1 1"/>
      </geometry>
      <material name="LightGrey"/>
    </visual>
    <collision>
      <origin rpy="0 0 0" xyz="0 0 0"/>
      <geometry>
        <mesh filename="tiago/meshes/arm/arm_5_collision.dae" scale="1 1 1"/>
      </geometry>
    </collision>
  </link>
  <joint name="arm_5_joint" type="revolute">
    <parent link="arm_4_link"/>
    <child link="arm_5_link"/>
    <origin rpy="0.0 -1.57079632679 0.0" xyz="-0.162 0.02 0.027"/>
    <axis xyz="0 0 1"/>
    <limit effort="3" lower="-2.09439510239" upper="2.09439510239" velocity="1.95"/>
    <dynamics damping="1.0" friction="1.0"/>
    <safety_controller k_position="20" k_velocity="20" soft_lower_limit="-2.07439510239" soft_upper_limit="2.07439510239"/>
  </joint>
  <link name="arm_6_link">
    <inertial>
      <origin rpy="0.00000 0.00000 0.00000" xyz="0.00531 0.00021 0.00002"/>
      <mass value="0.28722"/>
      <inertia ixx="0.00005900000" ixy="-0.00000000000" ixz="-0.00000000000" iyy="0.00010600000" iyz="0.00000000000" izz="0.00012600000"/>
    </inertial>
    <visual>
      <origin rpy="0 0 0" xyz="0 0 0"/>
      <geometry>
        <mesh filename="tiago/meshes/arm/arm_6.stl" scale="1 1 1"/>
      </geometry>
      <material name="LightGrey"/>
    </visual>
    <collision>
      <origin rpy="0 0 0" xyz="0 0 0"/>
      <geometry>
        <mesh filename="tiago/meshes/arm/arm_6_collision.dae" scale="1 1 1"/>
      </geometry>
    </collision>
  </link>
  <joint name="arm_6_joint" type="revolute">
    <parent link="arm_5_link"/>
    <child link="arm_6_link"/>
    <origin rpy="0.0 -1.57079632679 -1.57079632679" xyz="0 0 0.15"/>
    <axis xyz="0 0 1"/>
    <limit effort="6.6" lower="-1.41371669412" upper="1.41371669412" velocity="1.76"/>
    <dynamics damping="1.0" friction="1.0"/>
    <safety_controller k_position="20" k_velocity="20" soft_lower_limit="-1.39371669412" soft_upper_limit="1.39371669412"/>
  </joint>


  <link name="arm_7_link">
    <inertial>
      <origin rpy="0.00000 0.00000 0.00000" xyz="0.00011 -0.00034 0.02405"/>
      <mass value="0.2"/>
      <inertia ixx="0.00001400000" ixy="-0.00000000000" ixz="-0.00000000000" iyy="0.00001400000" iyz="0.00000000000" izz="0.00000400000"/>
    </inertial>
    <visual>
      <origin rpy="0 0 0" xyz="0 0 0"/>
      <geometry>
        <cylinder length="0.034" radius="0.0225"/>
      </geometry>
      <material name="LightGrey"/>
    </visual>
    <collision>
      <origin rpy="0 0 0" xyz="0 0 0"/>
      <geometry>
        <cylinder length="0.034" radius="0.0225"/>
      </geometry>
    </collision>
  </link>
  <joint name="arm_7_joint" type="revolute">
    <parent link="arm_6_link"/>
    <child link="arm_7_link"/>
    <origin rpy="1.57079632679 0.0 1.57079632679" xyz="0.066 0 0"/>
    <axis xyz="0 0 1"/>
    <limit effort="6.6" lower="-2.09439510239" upper="2.09439510239" velocity="1.76"/>
    <dynamics damping="1.0" friction="1.0"/>
    <safety_controller k_position="20" k_velocity="20" soft_lower_limit="-2.07439510239" soft_upper_limit="2.07439510239"/>
  </joint>


 <joint name="hand_palm_joint" type="revolute">
    <parent link="arm_7_link"/>
    <child link="Palm"/>
    <origin rpy="0 0 1.570796327" xyz="0 0.009 0.115"/>
  </joint>
  <link name="Palm">
 <inertial>
      <mass value="0.1943"/>
      <origin rpy="0 0 0" xyz="0 0 0.06031"/>
      <inertia ixx="0.0000923" ixy="0" ixz="0" iyy="0.0000923" iyz="0" izz="0.5744954"/>
    </inertial>
    <visual>
      <geometry>
	<mesh filename="AllegroHand/right/base_link_right.wrl" scale="0.001 0.001 0.001"/>
      </geometry>
    </visual>
    <collision>
      <material>
	<color rgba="0 0 0 1"/>
      </material>
	<origin xyz="-0.009300 0 -0.0475" />
	<geometry>
	  <box size="0.0408 0.1130 0.095" />
	</geometry>
    </collision>
  </link>
  <link name="Index-base">
<inertial>
      <mass value="0.1943"/>
      <origin rpy="0 0 0" xyz="0 0 0.06031"/>
      <inertia ixx="0.0000923" ixy="0" ixz="0" iyy="0.0000923" iyz="0" izz="0.5744954"/>
    </inertial>
    <visual>
      <geometry>
        <mesh filename="AllegroHand/right/link_0_0.wrl" scale="0.001 0.001 0.001"/>
      </geometry>
      <origin xyz="0 0 0.0164" />
    </visual>
    <collision>
      <material>
	<color rgba="0 0 0 1"/>
      </material>
      <geometry>
        <box size="0.0196 0.0275 0.0164" />
      </geometry>
      <origin xyz="0 0 0.0082" />
    </collision>
  </link>
  <joint name="joint_0.0" type="revolute">
      <axis xyz="0 0 1" />
      <limit effort="1" lower="-0.47" upper="0.47" velocity="1" />
      <parent link="Palm" />
      <child link="Index-base" />
      <origin rpy="-0.08726646255 0 0" xyz="0 0.0435 -0.001542" />
  </joint>
  <link name="Index-proximal">
<inertial>
      <mass value="0.1943"/>
      <origin rpy="0 0 0" xyz="0 0 0.06031"/>
      <inertia ixx="0.0000923" ixy="0" ixz="0" iyy="0.0000923" iyz="0" izz="0.5744954"/>
    </inertial>
    <visual>
      <geometry>
        <mesh filename="AllegroHand/right/link_1_0.wrl" scale="0.001 0.001 0.001"/>
      </geometry>
      <origin rpy="1.5707963 -1.5707963 0" />
    </visual>
    <collision>
      <material>
	<color rgba="0 0 0 1"/>
      </material>
      <geometry>
        <box size="0.0196 0.0275 0.054" />
      </geometry>
      <origin xyz="0 0 0.027" />
    </collision>
  </link>
  <joint name="joint_1.0" type="revolute">
      <limit effort="1" lower="-0.196" upper="1.61" velocity="1" />
      <axis xyz="0 1 0" />
      <parent link="Index-base" />
      <child link="Index-proximal" />
      <origin xyz="0 0 0.0164" />
  </joint>
  <link name="Index-distal">
<inertial>
      <mass value="0.1943"/>
      <origin rpy="0 0 0" xyz="0 0 0.06031"/>
      <inertia ixx="0.0000923" ixy="0" ixz="0" iyy="0.0000923" iyz="0" izz="0.5744954"/>
    </inertial>
    <visual>
      <geometry>
        <mesh filename="AllegroHand/right/link_2_0.wrl" scale="0.001 0.001 0.001"/>
      </geometry>
      <origin rpy="-1.5707963 -1.5707963 0" />
    </visual>
    <collision>
      <material>
	<color rgba="0 0 0 1"/>
      </material>
      <geometry>
        <box size="0.0196 0.0275 0.0384" />
      </geometry>
      <origin xyz="0 0 0.0192" />
    </collision>
  </link>
  <joint name="joint_2.0" type="revolute">
      <axis xyz="0 1 0" />
      <limit effort="1" lower="-0.174" upper="1.709" velocity="1" />
      <parent link="Index-proximal" />
      <child link="Index-distal" />
      <origin xyz="0 0 0.054" />
  </joint>
  <link name="Index-last">
<inertial>
      <mass value="0.1943"/>
      <origin rpy="0 0 0" xyz="0 0 0.06031"/>
      <inertia ixx="0.0000923" ixy="0" ixz="0" iyy="0.0000923" iyz="0" izz="0.5744954"/>
    </inertial>
    <visual>
      <geometry>
        <mesh filename="AllegroHand/right/link_3_0.wrl" scale="0.001 0.001 0.001"/>
      </geometry>
      <origin rpy="-1.5707963 -1.5707963 0" />
    </visual>
    <collision>
      <material>
	<color rgba="0 0 0 1"/>
      </material>
      <geometry>
        <box size="0.0196 0.0275 0.0267" />
      </geometry>
      <origin xyz="0 0 0.01335" />
    </collision>
  </link>
  <joint name="joint_3.0" type="revolute">
      <axis xyz="0 1 0" />
      <limit effort="1" lower="-0.227" upper="1.618" velocity="1" />
      <parent link="Index-distal" />
      <child link="Index-last" />
      <origin xyz="0 0 0.0384" />
  </joint>
  <link name="link_3_0_tip">
<inertial>
      <mass value="0.1943"/>
      <origin rpy="0 0 0" xyz="0 0 0.06031"/>
      <inertia ixx="0.0000923" ixy="0" ixz="0" iyy="0.0000923" iyz="0" izz="0.5744954"/>
    </inertial>
    <visual>
      <geometry>
        <mesh filename="AllegroHand/right/sensing_tip.wrl" scale="0.001 0.001 0.001"/>
      </geometry>
      <origin rpy="1.5707963 0 1.5707963" xyz="0.0038 0 0.0142" />
    </visual>
    <collision>
      <material>
	<color rgba="1 1 1 1"/>
      </material>
      <geometry>
        <box size="0.019 0.023 0.025" />
      </geometry>
      <origin xyz="0.0043 0 0.0079" />
    </collision>
    <collision>
      <material>
	<color rgba="1 1 1 1"/>
      </material>
      <geometry>
        <cylinder length="0.019" radius="0.0115"/>
      </geometry>
      <origin rpy="0 -1.5707963 0" xyz="0.0043 0 0.0204" />
    </collision>
  </link>
  <joint name="joint_3_0_tip" type="fixed">
      <parent link="Index-last" />
      <child link="link_3_0_tip" />
      <origin xyz="0 0 0.0267" />
  </joint>
  <link name="Medium-base">
<inertial>
      <mass value="0.1943"/>
      <origin rpy="0 0 0" xyz="0 0 0.06031"/>
      <inertia ixx="0.0000923" ixy="0" ixz="0" iyy="0.0000923" iyz="0" izz="0.5744954"/>
    </inertial>
    <visual>
      <geometry>
        <mesh filename="AllegroHand/right/link_0_0.wrl" scale="0.001 0.001 0.001"/>
      </geometry>
      <origin xyz="0 0 0.0164" />
    </visual>
    <collision>
      <material>
	<color rgba="0 0 0 1"/>
      </material>
      <geometry>
        <box size="0.0196 0.0275 0.0164" />
      </geometry>
      <origin xyz="0 0 0.0082" />
    </collision>
  </link>
  <joint name="joint_4.0" type="revolute">
      <axis xyz="0 0 1" />
      <limit effort="1" lower="-0.47" upper="0.47" velocity="1" />
      <parent link="Palm" />
      <child link="Medium-base" />
      <origin xyz="0 0 0.0007" />
  </joint>
  <link name="Medium-proximal">
<inertial>
      <mass value="0.1943"/>
      <origin rpy="0 0 0" xyz="0 0 0.06031"/>
      <inertia ixx="0.0000923" ixy="0" ixz="0" iyy="0.0000923" iyz="0" izz="0.5744954"/>
    </inertial>
    <visual>
      <geometry>
        <mesh filename="AllegroHand/right/link_1_0.wrl" scale="0.001 0.001 0.001"/>
      </geometry>
      <origin rpy="1.5707963 -1.5707963 0" />
    </visual>
    <collision>
      <material>
	<color rgba="0 0 0 1"/>
      </material>
      <geometry>
        <box size="0.0196 0.0275 0.054" />
      </geometry>
      <origin xyz="0 0 0.027" />
    </collision>
  </link>
  <joint name="joint_5.0" type="revolute">
      <limit effort="1" lower="-0.196" upper="1.61" velocity="1" />
      <axis xyz="0 1 0" />
      <parent link="Medium-base" />
      <child link="Medium-proximal" />
      <origin xyz="0 0 0.0164" />
  </joint>
  <link name="Medium-distal">
<inertial>
      <mass value="0.1943"/>
      <origin rpy="0 0 0" xyz="0 0 0.06031"/>
      <inertia ixx="0.0000923" ixy="0" ixz="0" iyy="0.0000923" iyz="0" izz="0.5744954"/>
    </inertial>
    <visual>
      <geometry>
        <mesh filename="AllegroHand/right/link_2_0.wrl" scale="0.001 0.001 0.001"/>
      </geometry>
      <origin rpy="-1.5707963 -1.5707963 0" />
    </visual>
    <collision>
      <material>
	<color rgba="0 0 0 1"/>
      </material>
      <geometry>
        <box size="0.0196 0.0275 0.0384" />
      </geometry>
      <origin xyz="0 0 0.0192" />
    </collision>
  </link>
  <joint name="joint_6.0" type="revolute">
      <axis xyz="0 1 0" />
      <limit effort="1" lower="-0.174" upper="1.709" velocity="1" />
      <parent link="Medium-proximal" />
      <child link="Medium-distal" />
      <origin xyz="0 0 0.054" />
  </joint>
  <link name="Medium-last">
<inertial>
      <mass value="0.1943"/>
      <origin rpy="0 0 0" xyz="0 0 0.06031"/>
      <inertia ixx="0.0000923" ixy="0" ixz="0" iyy="0.0000923" iyz="0" izz="0.5744954"/>
    </inertial>
    <visual>
      <geometry>
        <mesh filename="AllegroHand/right/link_3_0.wrl" scale="0.001 0.001 0.001"/>
      </geometry>
      <origin rpy="-1.5707963 -1.5707963 0" />
    </visual>
    <collision>
      <material>
	<color rgba="0 0 0 1"/>
      </material>
      <geometry>
        <box size="0.0196 0.0275 0.0267" />
      </geometry>
      <origin xyz="0 0 0.01335" />
    </collision>
  </link>
  <joint name="joint_7.0" type="revolute">
      <axis xyz="0 1 0" />
      <limit effort="1" lower="-0.227" upper="1.618" velocity="1" />
      <parent link="Medium-distal" />
      <child link="Medium-last" />
      <origin xyz="0 0 0.0384" />
  </joint>
  <link name="link_7_0_tip">
<inertial>
      <mass value="0.1943"/>
      <origin rpy="0 0 0" xyz="0 0 0.06031"/>
      <inertia ixx="0.0000923" ixy="0" ixz="0" iyy="0.0000923" iyz="0" izz="0.5744954"/>
    </inertial>
    <visual>
      <geometry>
        <mesh filename="AllegroHand/right/sensing_tip.wrl" scale="0.001 0.001 0.001"/>
      </geometry>
      <origin rpy="1.5707963 0 1.5707963" xyz="0.0038 0 0.0142" />
    </visual>
    <collision>
      <material>
	<color rgba="1 1 1 1"/>
      </material>
      <geometry>
        <box size="0.019 0.023 0.025" />
      </geometry>
      <origin xyz="0.0043 0 0.0079" />
    </collision>
    <collision>
      <material>
	<color rgba="1 1 1 1"/>
      </material>
      <geometry>
        <cylinder length="0.019" radius="0.0115"/>
      </geometry>
      <origin rpy="0 -1.5707963 0" xyz="0.0043 0 0.0204" />
    </collision>
  </link>
  <joint name="joint_7_0_tip" type="fixed">
      <parent link="Medium-last" />
      <child link="link_7_0_tip" />
      <origin xyz="0 0 0.0267" />
  </joint>
  <link name="Ring-base">
<inertial>
      <mass value="0.1943"/>
      <origin rpy="0 0 0" xyz="0 0 0.06031"/>
      <inertia ixx="0.0000923" ixy="0" ixz="0" iyy="0.0000923" iyz="0" izz="0.5744954"/>
    </inertial>
    <visual>
      <geometry>
        <mesh filename="AllegroHand/right/link_0_0.wrl" scale="0.001 0.001 0.001"/>
      </geometry>
      <origin xyz="0 0 0.0164" />
    </visual>
    <collision>
      <material>
	<color rgba="0 0 0 1"/>
      </material>
      <geometry>
        <box size="0.0196 0.0275 0.0164" />
      </geometry>
      <origin xyz="0 0 0.0082" />
    </collision>
  </link>
  <joint name="joint_8.0" type="revolute">
      <axis xyz="0 0 1" />
      <limit effort="1" lower="-0.47" upper="0.47" velocity="1" />
      <parent link="Palm" />
      <child link="Ring-base" />
      <origin rpy="0.08726646255 0 0" xyz="0 -0.0435 -0.001542" />
  </joint>
  <link name="Ring-proximal">
<inertial>
      <mass value="0.1943"/>
      <origin rpy="0 0 0" xyz="0 0 0.06031"/>
      <inertia ixx="0.0000923" ixy="0" ixz="0" iyy="0.0000923" iyz="0" izz="0.5744954"/>
    </inertial>
    <visual>
      <geometry>
        <mesh filename="AllegroHand/right/link_1_0.wrl" scale="0.001 0.001 0.001"/>
      </geometry>
      <origin rpy="1.5707963 -1.5707963 0" />
    </visual>
    <collision>
      <material>
	<color rgba="0 0 0 1"/>
      </material>
      <geometry>
        <box size="0.0196 0.0275 0.054" />
      </geometry>
      <origin xyz="0 0 0.027" />
    </collision>
  </link>
  <joint name="joint_9.0" type="revolute">
      <limit effort="1" lower="-0.196" upper="1.61" velocity="1" />
      <axis xyz="0 1 0" />
      <parent link="Ring-base" />
      <child link="Ring-proximal" />
      <origin xyz="0 0 0.0164" />
  </joint>
  <link name="Ring-distal">
<inertial>
      <mass value="0.1943"/>
      <origin rpy="0 0 0" xyz="0 0 0.06031"/>
      <inertia ixx="0.0000923" ixy="0" ixz="0" iyy="0.0000923" iyz="0" izz="0.5744954"/>
    </inertial>
    <visual>
      <geometry>
        <mesh filename="AllegroHand/right/link_2_0.wrl" scale="0.001 0.001 0.001"/>
      </geometry>
      <origin rpy="-1.5707963 -1.5707963 0" />
    </visual>
    <collision>
      <material>
	<color rgba="0 0 0 1"/>
      </material>
      <geometry>
        <box size="0.0196 0.0275 0.0384" />
      </geometry>
      <origin xyz="0 0 0.0192" />
    </collision>
  </link>
  <joint name="joint_10.0" type="revolute">
      <axis xyz="0 1 0" />
      <limit effort="1" lower="-0.174" upper="1.709" velocity="1" />
      <parent link="Ring-proximal" />
      <child link="Ring-distal" />
      <origin xyz="0 0 0.054" />
  </joint>
  <link name="Ring-last">
<inertial>
      <mass value="0.1943"/>
      <origin rpy="0 0 0" xyz="0 0 0.06031"/>
      <inertia ixx="0.0000923" ixy="0" ixz="0" iyy="0.0000923" iyz="0" izz="0.5744954"/>
    </inertial>
    <visual>
      <geometry>
        <mesh filename="AllegroHand/right/link_3_0.wrl" scale="0.001 0.001 0.001"/>
      </geometry>
      <origin rpy="-1.5707963 -1.5707963 0" />
    </visual>
    <collision>
      <material>
	<color rgba="0 0 0 1"/>
      </material>
      <geometry>
        <box size="0.0196 0.0275 0.0267" />
      </geometry>
      <origin xyz="0 0 0.01335" />
    </collision>
  </link>
  <joint name="joint_11.0" type="revolute">
      <axis xyz="0 1 0" />
      <limit effort="1" lower="-0.227" upper="1.618" velocity="1" />
      <parent link="Ring-distal" />
      <child link="Ring-last" />
      <origin xyz="0 0 0.0384" />
  </joint>
  <link name="link_11_0_tip">
<inertial>
      <mass value="0.1943"/>
      <origin rpy="0 0 0" xyz="0 0 0.06031"/>
      <inertia ixx="0.0000923" ixy="0" ixz="0" iyy="0.0000923" iyz="0" izz="0.5744954"/>
    </inertial>
    <visual>
      <geometry>
        <mesh filename="AllegroHand/right/sensing_tip.wrl" scale="0.001 0.001 0.001"/>
      </geometry>
      <origin rpy="1.5707963 0 1.5707963" xyz="0.0038 0 0.0142" />
    </visual>
    <collision>
      <material>
	<color rgba="1 1 1 1"/>
      </material>
      <geometry>
        <box size="0.019 0.023 0.025" />
      </geometry>
      <origin xyz="0.0043 0 0.0079" />
    </collision>
    <collision>
      <material>
	<color rgba="1 1 1 1"/>
      </material>
      <geometry>
        <cylinder length="0.019" radius="0.0115"/>
      </geometry>
      <origin rpy="0 -1.5707963 0" xyz="0.0043 0 0.0204" />
    </collision>
  </link>
  <joint name="joint_11_0_tip" type="fixed">
      <parent link="Ring-last" />
      <child link="link_11_0_tip" />
      <origin xyz="0 0 0.0267" />
  </joint>



 <link name="Thumb-base">
<inertial>
      <mass value="0.1943"/>
      <origin rpy="0 0 0" xyz="0 0 0.06031"/>
      <inertia ixx="0.0000923" ixy="0" ixz="0" iyy="0.0000923" iyz="0" izz="0.5744954"/>
    </inertial>
    <visual>
      <geometry>
        <mesh filename="AllegroHand/right/link_12_0_right.wrl" scale="0.001 0.001 0.001"/>
      </geometry>
      <origin rpy="1.570796327 0 -1.570796327" xyz="-0.02775 0 0" />
    </visual>
    <collision>
      <material name="black"/>
      <geometry>
        <box size="0.0358 0.034 0.0455" />
      </geometry>
      <origin xyz="-0.0179 0.009 0.0145" />
    </collision>
  </link>
  <joint name="joint_12.0" type="revolute">
      <axis xyz="-1 0 0" />
      <limit effort="1" lower="0.263" upper="1.396" velocity="1" />
      <parent link="Palm" />
      <child link="Thumb-base" />
      <origin rpy="0 -1.65806278845 -1.5707963259" xyz="-0.0182 0.019333 -0.045987" />
  </joint>
  <link name="Thumb-proximal">
<inertial>
      <mass value="0.1943"/>
      <origin rpy="0 0 0" xyz="0 0 0.06031"/>
      <inertia ixx="0.0000923" ixy="0" ixz="0" iyy="0.0000923" iyz="0" izz="0.5744954"/>
    </inertial>
    <visual>
      <geometry>
        <mesh filename="AllegroHand/right/link_13_0.wrl" scale="0.001 0.001 0.001"/>
      </geometry>
      <origin xyz="0 0 0.016000001" />
    </visual>
    <collision>
      <material name="black"/>
      <geometry>
        <box size="0.0196 0.0275 0.0177" />
      </geometry>
      <origin xyz="0 0 0.00885" />
    </collision>
  </link>
  <joint name="joint_13.0" type="revolute">
      <axis xyz="0 0 1" />
      <limit effort="1" lower="-0.105" upper="1.163" velocity="1" />
      <parent link="Thumb-base" />
      <child link="Thumb-proximal" />
      <origin xyz="-0.027 0.005 0.0399" />
  </joint>
  <link name="Thumb-distal">
<inertial>
      <mass value="0.1943"/>
      <origin rpy="0 0 0" xyz="0 0 0.06031"/>
      <inertia ixx="0.0000923" ixy="0" ixz="0" iyy="0.0000923" iyz="0" izz="0.5744954"/>
    </inertial>
    <visual>
      <geometry>
        <mesh filename="AllegroHand/right/link_14_0.wrl" scale="0.001 0.001 0.001"/>
      </geometry>
      <origin rpy="-1.5707963259 1.5707963259 0" />
    </visual>
    <collision>
      <material name="black"/>
      <geometry>
        <box size="0.0196 0.0275 0.0514" />
      </geometry>
      <origin xyz="0 0 0.0257" />
    </collision>
  </link>
  <joint name="joint_14.0" type="revolute">
      <axis xyz="0 1 0" />
      <limit effort="1" lower="-0.189" upper="1.644" velocity="1" />
      <parent link="Thumb-proximal" />
      <child link="Thumb-distal" />
      <origin xyz="0 0 0.0177" />
  </joint>
  <link name="Thumb-last">
<inertial>
      <mass value="0.1943"/>
      <origin rpy="0 0 0" xyz="0 0 0.06031"/>
      <inertia ixx="0.0000923" ixy="0" ixz="0" iyy="0.0000923" iyz="0" izz="0.5744954"/>
    </inertial>
    <visual>
      <geometry>
        <mesh filename="AllegroHand/right/link_15_0.wrl" scale="0.001 0.001 0.001"/>
      </geometry>
      <origin rpy="1.5707963259 1.5707963259 0" />
    </visual>
    <collision>
      <material name="black"/>
      <geometry>
        <box size="0.0196 0.0275 0.0423" />
      </geometry>
      <origin xyz="0 0 0.02115" />
    </collision>
  </link>
  <joint name="joint_15.0" type="revolute">
      <axis xyz="0 1 0" />
      <limit effort="1" lower="-0.162" upper="1.719" velocity="1" />
      <parent link="Thumb-distal" />
      <child link="Thumb-last" />
      <origin xyz="0 0 0.0514" />
  </joint>
  <link name="link_15_0_tip">
<inertial>
      <mass value="0.1943"/>
      <origin rpy="0 0 0" xyz="0 0 0.06031"/>
      <inertia ixx="0.0000923" ixy="0" ixz="0" iyy="0.0000923" iyz="0" izz="0.5744954"/>
    </inertial>
    <visual>
      <geometry>
        <mesh filename="AllegroHand/right/sensing_tip.wrl" scale="0.001 0.001 0.001"/>
      </geometry>
      <origin rpy="1.5707963 0 1.5707963" xyz="0.0038 0 0.0142" />
    </visual>
    <collision>
      <material name="white"/>
      <geometry>
        <box size="0.019 0.023 0.025" />
      </geometry>
      <origin xyz="0.0043 0 0.0079" />
    </collision>
    <collision>
      <material name="white"/>
      <geometry>
        <cylinder length="0.019" radius="0.0115"/>
      </geometry>
      <origin rpy="0 -1.5707963 0" xyz="0.0043 0 0.0204" />
    </collision>
  </link>
  <joint name="joint_15_0_tip" type="fixed">
      <parent link="Thumb-last" />
      <child link="link_15_0_tip" />
      <origin xyz="0 0 0.0423" />
  </joint>




</robot>
