<?xml version="1.0" encoding="utf-8"?>
<!-- =================================================================================== -->
<!-- |    This document was autogenerated by xacro from kuka_kmr_iiwa_2.urdf.xacro     | -->
<!-- |    EDITING THIS FILE BY HAND IS NOT RECOMMENDED                                 | -->
<!-- =================================================================================== -->
<robot name="kuka_kmr_iiwa">
  <!-- <xacro:include filename="$(find kuka_lbr_arm_description)/urdf/macros/vg10_gripper_macro.urdf.xacro"/> -->
  <!-- <xacro:include filename="$(find kuka_lbr_arm_description)/urdf/macros/kinect_gazebo_macro.xacro"/> -->
  <!-- <xacro:include filename="$(find kuka_lbr_arm_description)/urdf/macros/vaccum_plugin.xacro"/> -->
  <!-- <xacro:include filename="$(find realsense2_description)/urdf/_d435.urdf.xacro" /> -->
  <!-- BASE FOOTPRINT -->
  <link name="base_footprint">
    <!-- <visual>
            <origin xyz="0.0 0 0" rpy="0 0 0" />
            <geometry>
              <box size="0.001 0.001 0.001" />
            </geometry>
        </visual> -->
  </link>
  <joint name="base_link_footprint_joint" type="fixed">
    <origin rpy="0 0 0" xyz="0 0 0"/>
    <parent link="base_footprint"/>
    <child link="base_link"/>
  </joint>
  <!-- KMR BASE_LINK -->
  <link name="base_link">
    <inertial>
      <mass value="200"/>
      <!-- <origin xyz="0 0 0.35" rpy="0 0 0"/> -->
      <origin rppy="0 0 0 " xyz="0 0 0.34125"/>
      <!--Add x= -0.5-->
      <!-- <inertia  ixx="7.39083" ixy="0.000"  ixz="0.0"  iyy="13.803"  iyz="0.0"  izz="13.0275" /> -->
      <inertia ixx="12.2113635" ixy="0.0" ixz="0.0" iyy="20.8348935" iyz="0.0" izz="17.519382"/>
    </inertial>
    <visual>
      <origin rpy="0 0 0" xyz="-0.5 0 0"/>
      <!-- <origin xyz="0 0 ${(h/2)}" rppy="0 0 0 " />  -->
      <geometry>
        <mesh filename="package://kuka_kmr_description/meshes/base/kmr_iiwa_mobile_base.dae"/>
        <!-- <box size="${w*scale} ${l*scale} ${h}" /> -->
      </geometry>
    </visual>
    <collision>
      <origin rppy="0 0 0 " xyz="0 0 0.34125"/>
      <!--Add x= -0.5-->
      <geometry>
        <!-- <mesh filename="package://kuka_kmr_description/meshes/base/kmr_iiwa_mobile_base.dae"/> -->
        <box size="0.8856 0.5166 0.6825"/>
      </geometry>
    </collision>
  </link>
  <gazebo reference="base_link">
    <mu1>0.3</mu1>
    <mu2>0.3</mu2>
    <!-- <fdir1 value="1 1 0"/> -->
  </gazebo>
  <!-- LASER SCAN LINK FRONT -->
  <link name="base_laser_front">
    <inertial>
      <origin rpy="0 0 0" xyz="0 0 0"/>
      <mass value="0.01"/>
      <inertia ixx="3.64583333333e-08" ixy="0" ixz="0" iyy="3.64583333333e-08" iyz="0" izz="3.125e-08"/>
    </inertial>
    <visual>
      <origin rpy="0 0 0" xyz="0 0 0"/>
      <geometry>
        <cylinder length="0.005" radius="0.0025"/>
      </geometry>
      <material name="blue"/>
    </visual>
    <collision>
      <origin rpy="0 0 0" xyz="0 0 0"/>
      <geometry>
        <cylinder length="0.005" radius="0.0025"/>
      </geometry>
    </collision>
  </link>
  <!-- JOINT FRONT_LASER_BASE and BASE LINK -->
  <joint name="joint_sensor_laser_front" type="fixed">
    <origin rpy="0 0 -0.785398163397" xyz="0.47 -0.265 0.135"/>
    <parent link="base_link"/>
    <child link="base_laser_front"/>
  </joint>
  <!-- LASER SCAN LINK REAR -->
  <link name="base_laser_rear">
    <inertial>
      <origin rpy="0 0 0" xyz="0 0 0"/>
      <mass value="0.01"/>
      <inertia ixx="3.64583333333e-08" ixy="0" ixz="0" iyy="3.64583333333e-08" iyz="0" izz="3.125e-08"/>
    </inertial>
    <visual>
      <origin rpy="0 0 0" xyz="0 0 0"/>
      <geometry>
        <cylinder length="0.005" radius="0.0025"/>
      </geometry>
      <material name="blue"/>
    </visual>
    <collision>
      <origin rpy="0 0 0" xyz="0 0 0"/>
      <geometry>
        <cylinder length="0.005" radius="0.0025"/>
      </geometry>
    </collision>
  </link>
  <!-- JOINT REAR_LASER_BASE and BASE LINK -->
  <joint name="joint_sensor_laser_rear" type="fixed">
    <origin rpy="0 0 2.35619449019" xyz="-0.47 0.28 0.135"/>
    <parent link="base_link"/>
    <child link="base_laser_rear"/>
  </joint>
  <joint name="kmr_base_link-lbr_base" type="fixed">
    <origin rpy="0 0 -1.570795" xyz="0.365 -0.18 0.66"/>
    <parent link="base_link"/>
    <child link="lbr_base"/>
  </joint>
  <!-- <link name="world"/> -->
  <link name="lbr_base">
    <visual>
      <origin rpy="0 0 0" xyz="0 0 0"/>
      <geometry>
        <mesh filename="package://kuka_lbr_arm_description/meshes/lbr_iiwa_14_r820/visual/base_link.dae"/>
      </geometry>
    </visual>
    <collision>
      <origin rpy="0 0 0" xyz="0 0 0"/>
      <geometry>
        <mesh filename="package://kuka_lbr_arm_description/meshes/lbr_iiwa_14_r820/collision/base_link.stl"/>
      </geometry>
    </collision>
    <inertial>
      <mass value="5"/>
      <inertia ixx="0.3" ixy="0.0" ixz="0.0" iyy="0.3" iyz="0.0" izz="0.3"/>
    </inertial>
  </link>
  <link name="link_1">
    <visual>
      <origin rpy="0 0 0" xyz="0 0 0"/>
      <geometry>
        <mesh filename="package://kuka_lbr_arm_description/meshes/lbr_iiwa_14_r820/visual/link_1.dae"/>
      </geometry>
    </visual>
    <collision>
      <origin rpy="0 0 0" xyz="0 0 0"/>
      <geometry>
        <mesh filename="package://kuka_lbr_arm_description/meshes/lbr_iiwa_14_r820/collision/link_1.stl"/>
      </geometry>
    </collision>
    <inertial>
      <mass value="1.0"/>
      <inertia ixx="0.03" ixy="0.0" ixz="0.0" iyy="0.03" iyz="0.0" izz="0.03"/>
    </inertial>
  </link>
  <link name="link_2">
    <visual>
      <origin rpy="0 0 0" xyz="0 0 0"/>
      <geometry>
        <mesh filename="package://kuka_lbr_arm_description/meshes/lbr_iiwa_14_r820/visual/link_2.dae"/>
      </geometry>
    </visual>
    <collision>
      <origin rpy="0 0 0" xyz="0 0 0"/>
      <geometry>
        <mesh filename="package://kuka_lbr_arm_description/meshes/lbr_iiwa_14_r820/collision/link_2.stl"/>
      </geometry>
    </collision>
    <inertial>
      <mass value="1.0"/>
      <inertia ixx="0.03" ixy="0.0" ixz="0.0" iyy="0.03" iyz="0.0" izz="0.03"/>
    </inertial>
  </link>
  <link name="link_3">
    <visual>
      <origin rpy="0 0 0" xyz="0 0 0"/>
      <geometry>
        <mesh filename="package://kuka_lbr_arm_description/meshes/lbr_iiwa_14_r820/visual/link_3.dae"/>
      </geometry>
    </visual>
    <collision>
      <origin rpy="0 0 0" xyz="0 0 0"/>
      <geometry>
        <mesh filename="package://kuka_lbr_arm_description/meshes/lbr_iiwa_14_r820/collision/link_3.stl"/>
      </geometry>
    </collision>
    <inertial>
      <mass value="1.0"/>
      <inertia ixx="0.03" ixy="0.0" ixz="0.0" iyy="0.03" iyz="0.0" izz="0.03"/>
    </inertial>
  </link>
  <link name="link_4">
    <visual>
      <origin rpy="0 0 0" xyz="0 0 0"/>
      <geometry>
        <mesh filename="package://kuka_lbr_arm_description/meshes/lbr_iiwa_14_r820/visual/link_4.dae"/>
      </geometry>
    </visual>
    <collision>
      <origin rpy="0 0 0" xyz="0 0 0"/>
      <geometry>
        <mesh filename="package://kuka_lbr_arm_description/meshes/lbr_iiwa_14_r820/collision/link_4.stl"/>
      </geometry>
    </collision>
    <inertial>
      <mass value="1.0"/>
      <inertia ixx="0.03" ixy="0.0" ixz="0.0" iyy="0.03" iyz="0.0" izz="0.03"/>
    </inertial>
  </link>
  <link name="link_5">
    <visual>
      <origin rpy="0 0 0" xyz="0 0 0"/>
      <geometry>
        <mesh filename="package://kuka_lbr_arm_description/meshes/lbr_iiwa_14_r820/visual/link_5.dae"/>
      </geometry>
    </visual>
    <collision>
      <origin rpy="0 0 0" xyz="0 0 0"/>
      <geometry>
        <mesh filename="package://kuka_lbr_arm_description/meshes/lbr_iiwa_14_r820/collision/link_5.stl"/>
      </geometry>
    </collision>
    <inertial>
      <mass value="1.0"/>
      <inertia ixx="0.03" ixy="0.0" ixz="0.0" iyy="0.03" iyz="0.0" izz="0.03"/>
    </inertial>
  </link>
  <link name="link_6">
    <visual>
      <origin rpy="0 0 0" xyz="0 0 0"/>
      <geometry>
        <mesh filename="package://kuka_lbr_arm_description/meshes/lbr_iiwa_14_r820/visual/link_6.dae"/>
      </geometry>
    </visual>
    <collision>
      <origin rpy="0 0 0" xyz="0 0 0"/>
      <geometry>
        <mesh filename="package://kuka_lbr_arm_description/meshes/lbr_iiwa_14_r820/collision/link_6.stl"/>
      </geometry>
    </collision>
    <inertial>
      <mass value="1.0"/>
      <inertia ixx="0.03" ixy="0.0" ixz="0.0" iyy="0.03" iyz="0.0" izz="0.03"/>
    </inertial>
  </link>
  <link name="link_7">
    <visual>
      <origin rpy="0 0 0" xyz="0 0 0"/>
      <geometry>
        <mesh filename="package://kuka_lbr_arm_description/meshes/lbr_iiwa_14_r820/visual/link_7.dae"/>
      </geometry>
    </visual>
    <collision>
      <origin rpy="0 0 0" xyz="0 0 0"/>
      <geometry>
        <mesh filename="package://kuka_lbr_arm_description/meshes/lbr_iiwa_14_r820/collision/link_7.stl"/>
      </geometry>
    </collision>
    <inertial>
      <mass value="1.0"/>
      <inertia ixx="0.03" ixy="0.0" ixz="0.0" iyy="0.03" iyz="0.0" izz="0.03"/>
    </inertial>
  </link>
  <!-- END OF LINK LIST -->
  <gazebo reference="lbr_base">
    <!-- <material>Gazebo/Orange</material> -->
    <turnGravityOff>false</turnGravityOff>
  </gazebo>
  <gazebo reference="link_1">
    <!-- <material>Gazebo/Orange</material> -->
    <turnGravityOff>false</turnGravityOff>
  </gazebo>
  <gazebo reference="link_2">
    <!-- <material>Gazebo/Orange</material> -->
    <turnGravityOff>false</turnGravityOff>
  </gazebo>
  <gazebo reference="link_3">
    <!-- <material>Gazebo/Orange</material> -->
    <turnGravityOff>false</turnGravityOff>
  </gazebo>
  <gazebo reference="link_4">
    <!-- <material>Gazebo/Orange</material> -->
    <turnGravityOff>false</turnGravityOff>
  </gazebo>
  <gazebo reference="link_5">
    <!-- <material>Gazebo/Orange</material> -->
    <turnGravityOff>false</turnGravityOff>
  </gazebo>
  <gazebo reference="link_6">
    <!-- <material>Gazebo/Black</material> -->
    <turnGravityOff>false</turnGravityOff>
  </gazebo>
  <gazebo reference="link_7">
    <!-- <material>Gazebo/Black</material> -->
    <turnGravityOff>false</turnGravityOff>
  </gazebo>
  <!-- JOINT LIST -->
  <joint name="joint_a1" type="revolute">
    <origin rpy="0 0 0" xyz="0 0 0"/>
    <parent link="lbr_base"/>
    <child link="link_1"/>
    <axis xyz="0 0 1"/>
    <limit effort="220" lower="-2.9668" upper="2.9668" velocity="1.4834"/>
  </joint>
  <joint name="joint_a2" type="revolute">
    <origin rpy="0 0 0" xyz="-0.00043624 0 0.36"/>
    <parent link="link_1"/>
    <child link="link_2"/>
    <axis xyz="0 1 0"/>
    <limit effort="440" lower="-2.0942" upper="2.0942" velocity="1.4834"/>
    <dynamics damping="0.0" friction="0.0"/>
  </joint>
  <joint name="joint_a3" type="revolute">
    <origin rpy="0 0 0" xyz="0 0 0"/>
    <parent link="link_2"/>
    <child link="link_3"/>
    <axis xyz="0 0 1"/>
    <limit effort="220" lower="-2.9668" upper="2.9668" velocity="1.7452"/>
  </joint>
  <joint name="joint_a4" type="revolute">
    <origin rpy="0 0 0" xyz="0.00043624 0 0.42"/>
    <parent link="link_3"/>
    <child link="link_4"/>
    <axis xyz="0 -1 0"/>
    <limit effort="220" lower="-2.0942" upper="2.0942" velocity="1.3089"/>
  </joint>
  <joint name="joint_a5" type="revolute">
    <origin rpy="0 0 0" xyz="0 0 0"/>
    <parent link="link_4"/>
    <child link="link_5"/>
    <axis xyz="0 0 1"/>
    <limit effort="220" lower="-2.9668" upper="2.9668" velocity="2.2688"/>
  </joint>
  <joint name="joint_a6" type="revolute">
    <origin rpy="0 0 0" xyz="0 0 0.4"/>
    <parent link="link_5"/>
    <child link="link_6"/>
    <axis xyz="0 1 0"/>
    <limit effort="220" lower="-2.0942" upper="2.0942" velocity="2.356"/>
  </joint>
  <joint name="joint_a7" type="revolute">
    <origin rpy="0 0 0" xyz="0 0 0"/>
    <parent link="link_6"/>
    <child link="link_7"/>
    <axis xyz="0 0 1"/>
    <limit effort="220" lower="-3.0541" upper="3.0541" velocity="2.356"/>
  </joint>
  <!-- END JOINT LIST -->
  <!-- TRANSMISSION LIST  -->
  <transmission name="trans_joint_a1">
    <type>transmission_interface/SimpleTransmission</type>
    <joint name="joint_a1">
      <hardwareInterface>hardware_interface/PositionJointInterface</hardwareInterface>
    </joint>
    <actuator name="joint_a1_motor">
      <!--  <hardwareInterface>hardware_interface/PositionJointInterface</hardwareInterface> -->
      <mechanicalReduction>1</mechanicalReduction>
    </actuator>
  </transmission>
  <transmission name="trans_joint_a2">
    <type>transmission_interface/SimpleTransmission</type>
    <joint name="joint_a2">
      <hardwareInterface>hardware_interface/PositionJointInterface</hardwareInterface>
    </joint>
    <actuator name="joint_a2_motor">
      <!--  <hardwareInterface>hardware_interface/PositionJointInterface</hardwareInterface> -->
      <mechanicalReduction>1</mechanicalReduction>
    </actuator>
  </transmission>
  <transmission name="trans_joint_a3">
    <type>transmission_interface/SimpleTransmission</type>
    <joint name="joint_a3">
      <hardwareInterface>hardware_interface/PositionJointInterface</hardwareInterface>
    </joint>
    <actuator name="joint_a3_motor">
      <!--  <hardwareInterface>hardware_interface/PositionJointInterface</hardwareInterface> -->
      <mechanicalReduction>1</mechanicalReduction>
    </actuator>
  </transmission>
  <transmission name="trans_joint_a4">
    <type>transmission_interface/SimpleTransmission</type>
    <joint name="joint_a4">
      <hardwareInterface>hardware_interface/PositionJointInterface</hardwareInterface>
    </joint>
    <actuator name="joint_a4_motor">
      <!--  <hardwareInterface>hardware_interface/PositionJointInterface</hardwareInterface> -->
      <mechanicalReduction>1</mechanicalReduction>
    </actuator>
  </transmission>
  <transmission name="trans_joint_a5">
    <type>transmission_interface/SimpleTransmission</type>
    <joint name="joint_a5">
      <hardwareInterface>hardware_interface/PositionJointInterface</hardwareInterface>
    </joint>
    <actuator name="joint_a5_motor">
      <!--  <hardwareInterface>hardware_interface/PositionJointInterface</hardwareInterface> -->
      <mechanicalReduction>1</mechanicalReduction>
    </actuator>
  </transmission>
  <transmission name="trans_joint_a6">
    <type>transmission_interface/SimpleTransmission</type>
    <joint name="joint_a6">
      <hardwareInterface>hardware_interface/PositionJointInterface</hardwareInterface>
    </joint>
    <actuator name="joint_a6_motor">
      <!--  <hardwareInterface>hardware_interface/PositionJointInterface</hardwareInterface> -->
      <mechanicalReduction>1</mechanicalReduction>
    </actuator>
  </transmission>
  <transmission name="trans_joint_a7">
    <type>transmission_interface/SimpleTransmission</type>
    <joint name="joint_a7">
      <hardwareInterface>hardware_interface/PositionJointInterface</hardwareInterface>
    </joint>
    <actuator name="joint_a7_motor">
      <!--  <hardwareInterface>hardware_interface/PositionJointInterface</hardwareInterface> -->
      <mechanicalReduction>1</mechanicalReduction>
    </actuator>
  </transmission>
  <!-- END TRANSMISSION LIST -->
  <!-- GAZEBO ROS_CONTROL PLUGIN-->
  <gazebo>
    <plugin filename="libgazebo_ros_control.so" name="gazebo_ros_control">
      <robotNamespace>/lbr_controller</robotNamespace>
    </plugin>
  </gazebo>
  <!-- <xacro:vg10_gripper  tool_link="vg10" parent_link ="link_7"/> -->
  <!-- <xacro:kinect_macro  link_name="kinect" parent_link="vg10" /> -->
  <!-- <xacro:sensor_d435 parent="link_7" visualization="0">
            <origin xyz="-0.10 0 0.21" rpy="0 -${PI/2} 0"/> 
        </xacro:sensor_d435>
        
        <xacro:vaccum_plugin parent_link="vg10" x= "0.120" y ="0.0" z="0.0"/>

		<xacro:omni_steering/>
		<xacro:laser_scans visualize="false" laser_front_on="true" laser_rear_on="true"/> -->
</robot>
